Workbook
Name electron: 'Lines by Gauss'!#REF!
Name intensity1: #REF!
Name intensity10: #REF!
Name intensity2: #REF!
Name intensity3: #REF!
Name intensity4: #REF!
Name intensity5: #REF!
Name intensity6: #REF!
Name intensity7: #REF!
Name intensity8: #REF!
Name intensity9: #REF!
Name k_boltzman: 'Lines by Gauss'!#REF!
Name point1: 'Lines by Gauss'!$B$2:$B$2
Name point10: 'Lines by Gauss'!$B$11:$B$11
Name point2: 'Lines by Gauss'!$B$3:$E$3
Name point3: 'Lines by Gauss'!$B$4:$E$4
Name point4: 'Lines by Gauss'!$B$5:$E$5
Name point5: 'Lines by Gauss'!#REF!
Name point6: 'Lines by Gauss'!$B$7:$B$7
Name point7: 'Lines by Gauss'!$B$8:$B$8
Name point8: 'Lines by Gauss'!$B$9:$B$9
Name point9: 'Lines by Gauss'!$B$10:$B$10

Sheet Lines by Gauss
B3: λ, nm | C3: 465.1119 | E3: 510.5537 | G3: 515.323 | I3: 521.8197 | K3: 570.0237 | M3: 578.2127
B4: E, eV | C4: 7.737547 | E4: 3.816948 | G4: 6.191593 | I4: 6.192444 | K4: 3.816948 | M4: 3.78615 | Q4: k | R4: j=0 | S4: j=1 | T4: j=2 | U4: j=3 | V4: j=4 | W4: j=5 | X4: j=6 | Y4: j=7 | Z4: j=8 | AA4: j=9
B5: gf | C5: 1.4217765 | E5: 0.0197 | G5: 1.64659 | I5: 1.9716688 | K5: 0.0056505367 | M5: 0.013 | Q5: 0 | R5: 7.625972 | S5: 0.463415 | T5: 0 | U5: 0 | V5: 0 | W5: 0 | X5: 0 | Y5: 0 | Z5: 0 | AA5: 0
B6: r, mm | C6: I, a.u. | D6: r, mm | E6: I, a.u. | F6: r, mm | G6: I, a.u. | H6: r, mm | I6: I, a.u. | J6: r, mm | K6: I, a.u. | L6: r, mm | M6: I, a.u. | Q6: 1 | R6: -5.800962 | S6: 3.6063 | T6: 0.323954 | U6: 0 | V6: 0 | W6: 0 | X6: 0 | Y6: 0 | Z6: 0 | AA6: 0
B7: 0 | D7: 0 | F7: =F8-F$16/9 -> 0 | H7: 0 | J7: 0 | L7: 0 | Q7: 2 | R7: -0.584698 | S7: -2.951278 | T7: 2.653847 | U7: 0.263182 | V7: 0 | W7: 0 | X7: 0 | Y7: 0 | Z7: 0 | AA7: 0
B8: =B9-B$16/9 -> 0 | D8: =D9-D$16/9 -> 0 | F8: =F9-F$16/9 -> 0 | H8: =H9-H$16/9 -> 0 | J8: =J9-J$16/9 -> 0 | L8: =L9-L$16/9 -> 0 | Q8: 3 | R8: -0.339474 | S8: -0.182401 | T8: -2.058371 | U8: 2.198581 | V8: 0.227286 | W8: 0 | X8: 0 | Y8: 0 | Z8: 0 | AA8: 0
B9: =B10-B$16/9 -> 0 | D9: =D10-D$16/9 -> 0 | F9: =F10-F$16/9 -> 0 | H9: =H10-H$16/9 -> 0 | J9: =J10-J$16/9 -> 0 | L9: =L10-L$16/9 -> 0 | Q9: 4 | R9: -0.197038 | S9: -0.214891 | T9: -0.138728 | U9: -1.666071 | V9: 1.918418 | W9: 0.202929 | X9: 0 | Y9: 0 | Z9: 0 | AA9: 0
B10: =B11-B$16/9 -> 0 | D10: =D11-D$16/9 -> 0 | F10: =F11-F$16/9 -> 0 | H10: =H11-H$16/9 -> 0 | J10: =J11-J$16/9 -> 0 | L10: =L11-L$16/9 -> 0 | Q10: 5 | R10: -0.126877 | S10: -0.134649 | T10: -0.162498 | U10: -0.112322 | V10: -1.434904 | W10: 1.723807 | X10: 0.18502 | Y10: 0 | Z10: 0 | AA10: 0
B11: =B12-B$16/9 -> 0 | D11: =D12-D$16/9 -> 0 | F11: =F12-F$16/9 -> 0 | H11: =H12-H$16/9 -> 0 | J11: =J12-J$16/9 -> 0 | L11: =L12-L$16/9 -> 0 | Q11: 6 | R11: -0.088278 | S11: -0.092042 | T11: -0.105026 | U11: -0.133815 | V11: -0.095626 | W11: -1.278587 | X11: 1.578512 | Y11: 0.171141 | Z11: 0 | AA11: 0
B12: =B13-B$16/9 -> 0 | D12: =D13-D$16/9 -> 0 | F12: =F13-F$16/9 -> 0 | H12: =H13-H$16/9 -> 0 | J12: =J13-J$16/9 -> 0 | L12: =L13-L$16/9 -> 0 | Q12: 7 | R12: -0.064907 | S12: -0.066934 | T12: -0.073682 | U12: -0.087694 | V12: -0.115548 | W12: -0.084151 | X12: -1.164009 | Y12: 1.464693 | Z12: 0.159977 | AA12: 0
B13: =B14-B$16/9 -> 0 | D13: =D14-D$16/9 -> 0 | F13: =F14-F$16/9 -> 0 | H13: =H14-H$16/9 -> 0 | J13: =J14-J$16/9 -> 0 | L13: =L14-L$16/9 -> 0 | Q13: 8 | R13: -0.04825 | S13: -0.04941 | T13: -0.053181 | U13: -0.060617 | V13: -0.074289 | W13: -0.100408 | X13: -0.072617 | Y13: -1.070717 | Z13: 1.381857 | AA13: 0.251406
B14: =B15-B$16/9 -> 0 | D14: =D15-D$16/9 -> 0 | F14: =F15-F$16/9 -> 0 | H14: =H15-H$16/9 -> 0 | J14: =J15-J$16/9 -> 0 | L14: =L15-L$16/9 -> 0 | Q14: 9 | R14: -0.044883 | S14: -0.045711 | T14: -0.048354 | U14: -0.053365 | V14: -0.061987 | W14: -0.076986 | X14: -0.104895 | Y14: -0.086465 | Z14: -1.03729 | AA14: 0.984158
B15: =B16-B$16/9 -> 0 | D15: =D16-D$16/9 -> 0 | F15: =F16-F$16/9 -> 0 | H15: =H16-H$16/9 -> 0 | J15: =J16-J$16/9 -> 0 | L15: =L16-L$16/9 -> 0 | Q15: s | R15: 9.609 | S15: 4.695 | T15: 3.384 | U15: 2.779 | V15: 2.413 | W15: 2.161 | X15: 1.974 | Y15: 1.824 | Z15: 1.735 | AA15: 1.016
A16: rmax, mm
B18: Filter NG8 | C18: 0.26369 | E18: 0.24466 | G18: 0.24466 | I18: 0.2462 | K18: 0.25622 | M18: 0.25165
B19: y0
B20: xc
B21: w | Q21: j | R21: 0 | S21: 1 | T21: 2 | U21: 3 | V21: 4 | W21: 5 | X21: 6 | Y21: 7 | Z21: 8 | AA21: 9
B22: A | O22: rmax, m
O23: =B16*0.001 -> 0 | Q23: 465.1119 | R23: =(R$5*$C$24+R$6*$C$25+R$7*$C$26+R$8*$C$27+R$9*$C$28+R$10*$C$29+R$11*$C$30+R$12*$C$31+R$13*$C$32+R$14*$C$33)/$O$23 -> #DIV/0! | S23: =(S$5*$C$24+S$6*$C$25+S$7*$C$26+S$8*$C$27+S$9*$C$28+S$10*$C$29+S$11*$C$30+S$12*$C$31+S$13*$C$32+S$14*$C$33)/$O$23 -> #DIV/0! | T23: =(T$5*$C$24+T$6*$C$25+T$7*$C$26+T$8*$C$27+T$9*$C$28+T$10*$C$29+T$11*$C$30+T$12*$C$31+T$13*$C$32+T$14*$C$33)/$O$23 -> #DIV/0! | U23: =(U$5*$C$24+U$6*$C$25+U$7*$C$26+U$8*$C$27+U$9*$C$28+U$10*$C$29+U$11*$C$30+U$12*$C$31+U$13*$C$32+U$14*$C$33)/$O$23 -> #DIV/0! | V23: =(V$5*$C$24+V$6*$C$25+V$7*$C$26+V$8*$C$27+V$9*$C$28+V$10*$C$29+V$11*$C$30+V$12*$C$31+V$13*$C$32+V$14*$C$33)/$O$23 -> #DIV/0! | W23: =(W$5*$C$24+W$6*$C$25+W$7*$C$26+W$8*$C$27+W$9*$C$28+W$10*$C$29+W$11*$C$30+W$12*$C$31+W$13*$C$32+W$14*$C$33)/$O$23 -> #DIV/0! | X23: =(X$5*$C$24+X$6*$C$25+X$7*$C$26+X$8*$C$27+X$9*$C$28+X$10*$C$29+X$11*$C$30+X$12*$C$31+X$13*$C$32+X$14*$C$33)/$O$23 -> #DIV/0! | Y23: =(Y$5*$C$24+Y$6*$C$25+Y$7*$C$26+Y$8*$C$27+Y$9*$C$28+Y$10*$C$29+Y$11*$C$30+Y$12*$C$31+Y$13*$C$32+Y$14*$C$33)/$O$23 -> #DIV/0! | ... AA23: =(AA$5*$C$24+AA$6*$C$25+AA$7*$C$26+AA$8*$C$27+AA$9*$C$28+AA$10*$C$29+AA$11*$C$30+AA$12*$C$31+AA$13*$C$32+AA$14*$C$33)/$O$23 -> #DIV/0!
B24: 0 | C24: =(C$19+(C$22/(C$21*SQRT(3.14/2)))*EXP(-2*(($B24-C$20)/C$21)^2)) -> #DIV/0! | D24: 0 | E24: =(E$19+(E$22/(E$21*SQRT(3.14/2)))*EXP(-2*((D24-E$20)/E$21)^2)) -> #DIV/0! | F24: 0 | G24: =(G$19+(G$22/(G$21*SQRT(3.14/2)))*EXP(-2*((F24-G$20)/G$21)^2)) -> #DIV/0! | H24: 0 | I24: =(I$19+(I$22/(I$21*SQRT(3.14/2)))*EXP(-2*((H24-I$20)/I$21)^2)) -> #DIV/0! | J24: 0 | K24: =(K$19+(K$22/(K$21*SQRT(3.14/2)))*EXP(-2*((J24-K$20)/K$21)^2)) -> #DIV/0! | L24: 0 | M24: =(M$19+(M$22/(M$21*SQRT(3.14/2)))*EXP(-2*((L24-M$20)/M$21)^2)) -> #DIV/0! | O24: =D16*0.001 -> 0 | Q24: 510.5537 | R24: =(R$5*$E$24+R$6*$E$25+R$7*$E$26+R$8*$E$27+R$9*$E$28+R$10*$E$29+R$11*$E$30+R$12*$E$31+R$13*$E$32+R$14*$E$33)/$O$24 -> #DIV/0! | S24: =(S$5*$E$24+S$6*$E$25+S$7*$E$26+S$8*$E$27+S$9*$E$28+S$10*$E$29+S$11*$E$30+S$12*$E$31+S$13*$E$32+S$14*$E$33)/$O$24 -> #DIV/0! | T24: =(T$5*$E$24+T$6*$E$25+T$7*$E$26+T$8*$E$27+T$9*$E$28+T$10*$E$29+T$11*$E$30+T$12*$E$31+T$13*$E$32+T$14*$E$33)/$O$24 -> #DIV/0! | U24: =(U$5*$E$24+U$6*$E$25+U$7*$E$26+U$8*$E$27+U$9*$E$28+U$10*$E$29+U$11*$E$30+U$12*$E$31+U$13*$E$32+U$14*$E$33)/$O$24 -> #DIV/0! | V24: =(V$5*$E$24+V$6*$E$25+V$7*$E$26+V$8*$E$27+V$9*$E$28+V$10*$E$29+V$11*$E$30+V$12*$E$31+V$13*$E$32+V$14*$E$33)/$O$24 -> #DIV/0! | W24: =(W$5*$E$24+W$6*$E$25+W$7*$E$26+W$8*$E$27+W$9*$E$28+W$10*$E$29+W$11*$E$30+W$12*$E$31+W$13*$E$32+W$14*$E$33)/$O$24 -> #DIV/0! | X24: =(X$5*$E$24+X$6*$E$25+X$7*$E$26+X$8*$E$27+X$9*$E$28+X$10*$E$29+X$11*$E$30+X$12*$E$31+X$13*$E$32+X$14*$E$33)/$O$24 -> #DIV/0! | Y24: =(Y$5*$E$24+Y$6*$E$25+Y$7*$E$26+Y$8*$E$27+Y$9*$E$28+Y$10*$E$29+Y$11*$E$30+Y$12*$E$31+Y$13*$E$32+Y$14*$E$33)/$O$24 -> #DIV/0! | ... AA24: =(AA$5*$E$24+AA$6*$E$25+AA$7*$E$26+AA$8*$E$27+AA$9*$E$28+AA$10*$E$29+AA$11*$E$30+AA$12*$E$31+AA$13*$E$32+AA$14*$E$33)/$O$24 -> #DIV/0!
B25: =B24+B$16/9 -> 0 | C25: =(C$19+(C$22/(C$21*SQRT(3.14/2)))*EXP(-2*(($B25-C$20)/C$21)^2)) -> #DIV/0! | D25: =D24+D$16/9 -> 0 | E25: =(E$19+(E$22/(E$21*SQRT(3.14/2)))*EXP(-2*((D25-E$20)/E$21)^2)) -> #DIV/0! | F25: =F24+F$16/9 -> 0 | G25: =(G$19+(G$22/(G$21*SQRT(3.14/2)))*EXP(-2*((F25-G$20)/G$21)^2)) -> #DIV/0! | H25: =H24+H$16/9 -> 0 | I25: =(I$19+(I$22/(I$21*SQRT(3.14/2)))*EXP(-2*((H25-I$20)/I$21)^2)) -> #DIV/0! | J25: =J24+J$16/9 -> 0 | K25: =(K$19+(K$22/(K$21*SQRT(3.14/2)))*EXP(-2*((J25-K$20)/K$21)^2)) -> #DIV/0! | L25: =L24+L$16/9 -> 0 | M25: =(M$19+(M$22/(M$21*SQRT(3.14/2)))*EXP(-2*((L25-M$20)/M$21)^2)) -> #DIV/0! | O25: =F16*0.001 -> 0 | Q25: 515.323 | R25: =(R$5*$G$24+R$6*$G$25+R$7*$G$26+R$8*$G$27+R$9*$G$28+R$10*$G$29+R$11*$G$30+R$12*$G$31+R$13*$G$32+R$14*$G$33)/$O$25 -> #DIV/0! | S25: =(S$5*$G$24+S$6*$G$25+S$7*$G$26+S$8*$G$27+S$9*$G$28+S$10*$G$29+S$11*$G$30+S$12*$G$31+S$13*$G$32+S$14*$G$33)/$O$25 -> #DIV/0! | T25: =(T$5*$G$24+T$6*$G$25+T$7*$G$26+T$8*$G$27+T$9*$G$28+T$10*$G$29+T$11*$G$30+T$12*$G$31+T$13*$G$32+T$14*$G$33)/$O$25 -> #DIV/0! | U25: =(U$5*$G$24+U$6*$G$25+U$7*$G$26+U$8*$G$27+U$9*$G$28+U$10*$G$29+U$11*$G$30+U$12*$G$31+U$13*$G$32+U$14*$G$33)/$O$25 -> #DIV/0! | V25: =(V$5*$G$24+V$6*$G$25+V$7*$G$26+V$8*$G$27+V$9*$G$28+V$10*$G$29+V$11*$G$30+V$12*$G$31+V$13*$G$32+V$14*$G$33)/$O$25 -> #DIV/0! | W25: =(W$5*$G$24+W$6*$G$25+W$7*$G$26+W$8*$G$27+W$9*$G$28+W$10*$G$29+W$11*$G$30+W$12*$G$31+W$13*$G$32+W$14*$G$33)/$O$25 -> #DIV/0! | X25: =(X$5*$G$24+X$6*$G$25+X$7*$G$26+X$8*$G$27+X$9*$G$28+X$10*$G$29+X$11*$G$30+X$12*$G$31+X$13*$G$32+X$14*$G$33)/$O$25 -> #DIV/0! | Y25: =(Y$5*$G$24+Y$6*$G$25+Y$7*$G$26+Y$8*$G$27+Y$9*$G$28+Y$10*$G$29+Y$11*$G$30+Y$12*$G$31+Y$13*$G$32+Y$14*$G$33)/$O$25 -> #DIV/0! | ... AA25: =(AA$5*$G$24+AA$6*$G$25+AA$7*$G$26+AA$8*$G$27+AA$9*$G$28+AA$10*$G$29+AA$11*$G$30+AA$12*$G$31+AA$13*$G$32+AA$14*$G$33)/$O$25 -> #DIV/0!
B26: =B25+B$16/9 -> 0 | C26: =(C$19+(C$22/(C$21*SQRT(3.14/2)))*EXP(-2*(($B26-C$20)/C$21)^2)) -> #DIV/0! | D26: =D25+D$16/9 -> 0 | E26: =(E$19+(E$22/(E$21*SQRT(3.14/2)))*EXP(-2*((D26-E$20)/E$21)^2)) -> #DIV/0! | F26: =F25+F$16/9 -> 0 | G26: =(G$19+(G$22/(G$21*SQRT(3.14/2)))*EXP(-2*((F26-G$20)/G$21)^2)) -> #DIV/0! | H26: =H25+H$16/9 -> 0 | I26: =(I$19+(I$22/(I$21*SQRT(3.14/2)))*EXP(-2*((H26-I$20)/I$21)^2)) -> #DIV/0! | J26: =J25+J$16/9 -> 0 | K26: =(K$19+(K$22/(K$21*SQRT(3.14/2)))*EXP(-2*((J26-K$20)/K$21)^2)) -> #DIV/0! | L26: =L25+L$16/9 -> 0 | M26: =(M$19+(M$22/(M$21*SQRT(3.14/2)))*EXP(-2*((L26-M$20)/M$21)^2)) -> #DIV/0! | O26: =H16*0.001 -> 0 | Q26: 521.8197 | R26: =(R$5*$I$24+R$6*$I$25+R$7*$I$26+R$8*$I$27+R$9*$I$28+R$10*$I$29+R$11*$I$30+R$12*$I$31+R$13*$I$32+R$14*$I$33)/$O$26 -> #DIV/0! | S26: =(S$5*$I$24+S$6*$I$25+S$7*$I$26+S$8*$I$27+S$9*$I$28+S$10*$I$29+S$11*$I$30+S$12*$I$31+S$13*$I$32+S$14*$I$33)/$O$26 -> #DIV/0! | T26: =(T$5*$I$24+T$6*$I$25+T$7*$I$26+T$8*$I$27+T$9*$I$28+T$10*$I$29+T$11*$I$30+T$12*$I$31+T$13*$I$32+T$14*$I$33)/$O$26 -> #DIV/0! | U26: =(U$5*$I$24+U$6*$I$25+U$7*$I$26+U$8*$I$27+U$9*$I$28+U$10*$I$29+U$11*$I$30+U$12*$I$31+U$13*$I$32+U$14*$I$33)/$O$26 -> #DIV/0! | V26: =(V$5*$I$24+V$6*$I$25+V$7*$I$26+V$8*$I$27+V$9*$I$28+V$10*$I$29+V$11*$I$30+V$12*$I$31+V$13*$I$32+V$14*$I$33)/$O$26 -> #DIV/0! | W26: =(W$5*$I$24+W$6*$I$25+W$7*$I$26+W$8*$I$27+W$9*$I$28+W$10*$I$29+W$11*$I$30+W$12*$I$31+W$13*$I$32+W$14*$I$33)/$O$26 -> #DIV/0! | X26: =(X$5*$I$24+X$6*$I$25+X$7*$I$26+X$8*$I$27+X$9*$I$28+X$10*$I$29+X$11*$I$30+X$12*$I$31+X$13*$I$32+X$14*$I$33)/$O$26 -> #DIV/0! | Y26: =(Y$5*$I$24+Y$6*$I$25+Y$7*$I$26+Y$8*$I$27+Y$9*$I$28+Y$10*$I$29+Y$11*$I$30+Y$12*$I$31+Y$13*$I$32+Y$14*$I$33)/$O$26 -> #DIV/0! | ... AA26: =(AA$5*$I$24+AA$6*$I$25+AA$7*$I$26+AA$8*$I$27+AA$9*$I$28+AA$10*$I$29+AA$11*$I$30+AA$12*$I$31+AA$13*$I$32+AA$14*$I$33)/$O$26 -> #DIV/0!
B27: =B26+B$16/9 -> 0 | C27: =(C$19+(C$22/(C$21*SQRT(3.14/2)))*EXP(-2*(($B27-C$20)/C$21)^2)) -> #DIV/0! | D27: =D26+D$16/9 -> 0 | E27: =(E$19+(E$22/(E$21*SQRT(3.14/2)))*EXP(-2*((D27-E$20)/E$21)^2)) -> #DIV/0! | F27: =F26+F$16/9 -> 0 | G27: =(G$19+(G$22/(G$21*SQRT(3.14/2)))*EXP(-2*((F27-G$20)/G$21)^2)) -> #DIV/0! | H27: =H26+H$16/9 -> 0 | I27: =(I$19+(I$22/(I$21*SQRT(3.14/2)))*EXP(-2*((H27-I$20)/I$21)^2)) -> #DIV/0! | J27: =J26+J$16/9 -> 0 | K27: =(K$19+(K$22/(K$21*SQRT(3.14/2)))*EXP(-2*((J27-K$20)/K$21)^2)) -> #DIV/0! | L27: =L26+L$16/9 -> 0 | M27: =(M$19+(M$22/(M$21*SQRT(3.14/2)))*EXP(-2*((L27-M$20)/M$21)^2)) -> #DIV/0! | O27: =J16*0.001 -> 0 | Q27: 570.0237 | R27: =(R$5*$K$24+R$6*$K$25+R$7*$K$26+R$8*$K$27+R$9*$K$28+R$10*$K$29+R$11*$K$30+R$12*$K$31+R$13*$K$32+R$14*$K$33)/$O$27 -> #DIV/0! | S27: =(S$5*$K$24+S$6*$K$25+S$7*$K$26+S$8*$K$27+S$9*$K$28+S$10*$K$29+S$11*$K$30+S$12*$K$31+S$13*$K$32+S$14*$K$33)/$O$27 -> #DIV/0! | T27: =(T$5*$K$24+T$6*$K$25+T$7*$K$26+T$8*$K$27+T$9*$K$28+T$10*$K$29+T$11*$K$30+T$12*$K$31+T$13*$K$32+T$14*$K$33)/$O$27 -> #DIV/0! | U27: =(U$5*$K$24+U$6*$K$25+U$7*$K$26+U$8*$K$27+U$9*$K$28+U$10*$K$29+U$11*$K$30+U$12*$K$31+U$13*$K$32+U$14*$K$33)/$O$27 -> #DIV/0! | V27: =(V$5*$K$24+V$6*$K$25+V$7*$K$26+V$8*$K$27+V$9*$K$28+V$10*$K$29+V$11*$K$30+V$12*$K$31+V$13*$K$32+V$14*$K$33)/$O$27 -> #DIV/0! | W27: =(W$5*$K$24+W$6*$K$25+W$7*$K$26+W$8*$K$27+W$9*$K$28+W$10*$K$29+W$11*$K$30+W$12*$K$31+W$13*$K$32+W$14*$K$33)/$O$27 -> #DIV/0! | X27: =(X$5*$K$24+X$6*$K$25+X$7*$K$26+X$8*$K$27+X$9*$K$28+X$10*$K$29+X$11*$K$30+X$12*$K$31+X$13*$K$32+X$14*$K$33)/$O$27 -> #DIV/0! | Y27: =(Y$5*$K$24+Y$6*$K$25+Y$7*$K$26+Y$8*$K$27+Y$9*$K$28+Y$10*$K$29+Y$11*$K$30+Y$12*$K$31+Y$13*$K$32+Y$14*$K$33)/$O$27 -> #DIV/0! | ... AA27: =(AA$5*$K$24+AA$6*$K$25+AA$7*$K$26+AA$8*$K$27+AA$9*$K$28+AA$10*$K$29+AA$11*$K$30+AA$12*$K$31+AA$13*$K$32+AA$14*$K$33)/$O$27 -> #DIV/0!
B28: =B27+B$16/9 -> 0 | C28: =(C$19+(C$22/(C$21*SQRT(3.14/2)))*EXP(-2*(($B28-C$20)/C$21)^2)) -> #DIV/0! | D28: =D27+D$16/9 -> 0 | E28: =(E$19+(E$22/(E$21*SQRT(3.14/2)))*EXP(-2*((D28-E$20)/E$21)^2)) -> #DIV/0! | F28: =F27+F$16/9 -> 0 | G28: =(G$19+(G$22/(G$21*SQRT(3.14/2)))*EXP(-2*((F28-G$20)/G$21)^2)) -> #DIV/0! | H28: =H27+H$16/9 -> 0 | I28: =(I$19+(I$22/(I$21*SQRT(3.14/2)))*EXP(-2*((H28-I$20)/I$21)^2)) -> #DIV/0! | J28: =J27+J$16/9 -> 0 | K28: =(K$19+(K$22/(K$21*SQRT(3.14/2)))*EXP(-2*((J28-K$20)/K$21)^2)) -> #DIV/0! | L28: =L27+L$16/9 -> 0 | M28: =(M$19+(M$22/(M$21*SQRT(3.14/2)))*EXP(-2*((L28-M$20)/M$21)^2)) -> #DIV/0! | O28: =L16*0.001 -> 0 | Q28: 578.2127 | R28: =(R$5*$M$24+R$6*$M$25+R$7*$M$26+R$8*$M$27+R$9*$M$28+R$10*$M$29+R$11*$M$30+R$12*$M$31+R$13*$M$32+R$14*$M$33)/$O$28 -> #DIV/0! | S28: =(S$5*$M$24+S$6*$M$25+S$7*$M$26+S$8*$M$27+S$9*$M$28+S$10*$M$29+S$11*$M$30+S$12*$M$31+S$13*$M$32+S$14*$M$33)/$O$28 -> #DIV/0! | T28: =(T$5*$M$24+T$6*$M$25+T$7*$M$26+T$8*$M$27+T$9*$M$28+T$10*$M$29+T$11*$M$30+T$12*$M$31+T$13*$M$32+T$14*$M$33)/$O$28 -> #DIV/0! | U28: =(U$5*$M$24+U$6*$M$25+U$7*$M$26+U$8*$M$27+U$9*$M$28+U$10*$M$29+U$11*$M$30+U$12*$M$31+U$13*$M$32+U$14*$M$33)/$O$28 -> #DIV/0! | V28: =(V$5*$M$24+V$6*$M$25+V$7*$M$26+V$8*$M$27+V$9*$M$28+V$10*$M$29+V$11*$M$30+V$12*$M$31+V$13*$M$32+V$14*$M$33)/$O$28 -> #DIV/0! | W28: =(W$5*$M$24+W$6*$M$25+W$7*$M$26+W$8*$M$27+W$9*$M$28+W$10*$M$29+W$11*$M$30+W$12*$M$31+W$13*$M$32+W$14*$M$33)/$O$28 -> #DIV/0! | X28: =(X$5*$M$24+X$6*$M$25+X$7*$M$26+X$8*$M$27+X$9*$M$28+X$10*$M$29+X$11*$M$30+X$12*$M$31+X$13*$M$32+X$14*$M$33)/$O$28 -> #DIV/0! | Y28: =(Y$5*$M$24+Y$6*$M$25+Y$7*$M$26+Y$8*$M$27+Y$9*$M$28+Y$10*$M$29+Y$11*$M$30+Y$12*$M$31+Y$13*$M$32+Y$14*$M$33)/$O$28 -> #DIV/0! | ... AA28: =(AA$5*$M$24+AA$6*$M$25+AA$7*$M$26+AA$8*$M$27+AA$9*$M$28+AA$10*$M$29+AA$11*$M$30+AA$12*$M$31+AA$13*$M$32+AA$14*$M$33)/$O$28 -> #DIV/0!
B29: =B28+B$16/9 -> 0 | C29: =(C$19+(C$22/(C$21*SQRT(3.14/2)))*EXP(-2*(($B29-C$20)/C$21)^2)) -> #DIV/0! | D29: =D28+D$16/9 -> 0 | E29: =(E$19+(E$22/(E$21*SQRT(3.14/2)))*EXP(-2*((D29-E$20)/E$21)^2)) -> #DIV/0! | F29: =F28+F$16/9 -> 0 | G29: =(G$19+(G$22/(G$21*SQRT(3.14/2)))*EXP(-2*((F29-G$20)/G$21)^2)) -> #DIV/0! | H29: =H28+H$16/9 -> 0 | I29: =(I$19+(I$22/(I$21*SQRT(3.14/2)))*EXP(-2*((H29-I$20)/I$21)^2)) -> #DIV/0! | J29: =J28+J$16/9 -> 0 | K29: =(K$19+(K$22/(K$21*SQRT(3.14/2)))*EXP(-2*((J29-K$20)/K$21)^2)) -> #DIV/0! | L29: =L28+L$16/9 -> 0 | M29: =(M$19+(M$22/(M$21*SQRT(3.14/2)))*EXP(-2*((L29-M$20)/M$21)^2)) -> #DIV/0!
B30: =B29+B$16/9 -> 0 | C30: =(C$19+(C$22/(C$21*SQRT(3.14/2)))*EXP(-2*(($B30-C$20)/C$21)^2)) -> #DIV/0! | D30: =D29+D$16/9 -> 0 | E30: =(E$19+(E$22/(E$21*SQRT(3.14/2)))*EXP(-2*((D30-E$20)/E$21)^2)) -> #DIV/0! | F30: =F29+F$16/9 -> 0 | G30: =(G$19+(G$22/(G$21*SQRT(3.14/2)))*EXP(-2*((F30-G$20)/G$21)^2)) -> #DIV/0! | H30: =H29+H$16/9 -> 0 | I30: =(I$19+(I$22/(I$21*SQRT(3.14/2)))*EXP(-2*((H30-I$20)/I$21)^2)) -> #DIV/0! | J30: =J29+J$16/9 -> 0 | K30: =(K$19+(K$22/(K$21*SQRT(3.14/2)))*EXP(-2*((J30-K$20)/K$21)^2)) -> #DIV/0! | L30: =L29+L$16/9 -> 0 | M30: =(M$19+(M$22/(M$21*SQRT(3.14/2)))*EXP(-2*((L30-M$20)/M$21)^2)) -> #DIV/0!
B31: =B30+B$16/9 -> 0 | C31: =(C$19+(C$22/(C$21*SQRT(3.14/2)))*EXP(-2*(($B31-C$20)/C$21)^2)) -> #DIV/0! | D31: =D30+D$16/9 -> 0 | E31: =(E$19+(E$22/(E$21*SQRT(3.14/2)))*EXP(-2*((D31-E$20)/E$21)^2)) -> #DIV/0! | F31: =F30+F$16/9 -> 0 | G31: =(G$19+(G$22/(G$21*SQRT(3.14/2)))*EXP(-2*((F31-G$20)/G$21)^2)) -> #DIV/0! | H31: =H30+H$16/9 -> 0 | I31: =(I$19+(I$22/(I$21*SQRT(3.14/2)))*EXP(-2*((H31-I$20)/I$21)^2)) -> #DIV/0! | J31: =J30+J$16/9 -> 0 | K31: =(K$19+(K$22/(K$21*SQRT(3.14/2)))*EXP(-2*((J31-K$20)/K$21)^2)) -> #DIV/0! | L31: =L30+L$16/9 -> 0 | M31: =(M$19+(M$22/(M$21*SQRT(3.14/2)))*EXP(-2*((L31-M$20)/M$21)^2)) -> #DIV/0!
B32: =B31+B$16/9 -> 0 | C32: =(C$19+(C$22/(C$21*SQRT(3.14/2)))*EXP(-2*(($B32-C$20)/C$21)^2)) -> #DIV/0! | D32: =D31+D$16/9 -> 0 | E32: =(E$19+(E$22/(E$21*SQRT(3.14/2)))*EXP(-2*((D32-E$20)/E$21)^2)) -> #DIV/0! | F32: =F31+F$16/9 -> 0 | G32: =(G$19+(G$22/(G$21*SQRT(3.14/2)))*EXP(-2*((F32-G$20)/G$21)^2)) -> #DIV/0! | H32: =H31+H$16/9 -> 0 | I32: =(I$19+(I$22/(I$21*SQRT(3.14/2)))*EXP(-2*((H32-I$20)/I$21)^2)) -> #DIV/0! | J32: =J31+J$16/9 -> 0 | K32: =(K$19+(K$22/(K$21*SQRT(3.14/2)))*EXP(-2*((J32-K$20)/K$21)^2)) -> #DIV/0! | L32: =L31+L$16/9 -> 0 | M32: =(M$19+(M$22/(M$21*SQRT(3.14/2)))*EXP(-2*((L32-M$20)/M$21)^2)) -> #DIV/0!
B33: =B16 -> 0 | C33: =(C$19+(C$22/(C$21*SQRT(3.14/2)))*EXP(-2*(($B33-C$20)/C$21)^2)) -> #DIV/0! | D33: =D16 -> 0 | E33: =(E$19+(E$22/(E$21*SQRT(3.14/2)))*EXP(-2*((D33-E$20)/E$21)^2)) -> #DIV/0! | F33: =F16 -> 0 | G33: =(G$19+(G$22/(G$21*SQRT(3.14/2)))*EXP(-2*((F33-G$20)/G$21)^2)) -> #DIV/0! | H33: =H16 -> 0 | I33: =(I$19+(I$22/(I$21*SQRT(3.14/2)))*EXP(-2*((H33-I$20)/I$21)^2)) -> #DIV/0! | J33: =J16 -> 0 | K33: =(K$19+(K$22/(K$21*SQRT(3.14/2)))*EXP(-2*((J33-K$20)/K$21)^2)) -> #DIV/0! | L33: =L16 -> 0 | M33: =(M$19+(M$22/(M$21*SQRT(3.14/2)))*EXP(-2*((L33-M$20)/M$21)^2)) -> #DIV/0!
G36: Abelized
B38: λ, nm | C38: 465.1119 | E38: 510.5537 | G38: 515.323 | I38: 521.8197 | K38: 570.0237 | M38: 578.2127
B39: r, mm | C39: I, a.u. | E39: I, a.u. | G39: I, a.u. | I39: I, a.u. | K39: I, a.u. | M39: I, a.u.
B40: =B24 -> 0 | C40: =(R$5*$C$24+R$6*$C$25+R$7*$C$26+R$8*$C$27+R$9*$C$28+R$10*$C$29+R$11*$C$30+R$12*$C$31+R$13*$C$32+R$14*$C$33)/$O$23 -> #DIV/0! | D40: =D24 -> 0 | E40: =(R$5*$E$24+R$6*$E$25+R$7*$E$26+R$8*$E$27+R$9*$E$28+R$10*$E$29+R$11*$E$30+R$12*$E$31+R$13*$E$32+R$14*$E$33)/$O$24 -> #DIV/0! | F40: =F24 -> 0 | G40: =(R$5*$G$24+R$6*$G$25+R$7*$G$26+R$8*$G$27+R$9*$G$28+R$10*$G$29+R$11*$G$30+R$12*$G$31+R$13*$G$32+R$14*$G$33)/$O$25 -> #DIV/0! | H40: =H24 -> 0 | I40: =(R$5*$I$24+R$6*$I$25+R$7*$I$26+R$8*$I$27+R$9*$I$28+R$10*$I$29+R$11*$I$30+R$12*$I$31+R$13*$I$32+R$14*$I$33)/$O$26 -> #DIV/0! | J40: =J24 -> 0 | K40: =(R$5*$K$24+R$6*$K$25+R$7*$K$26+R$8*$K$27+R$9*$K$28+R$10*$K$29+R$11*$K$30+R$12*$K$31+R$13*$K$32+R$14*$K$33)/$O$27 -> #DIV/0! | L40: =L24 -> 0 | M40: =(R$5*$M$24+R$6*$M$25+R$7*$M$26+R$8*$M$27+R$9*$M$28+R$10*$M$29+R$11*$M$30+R$12*$M$31+R$13*$M$32+R$14*$M$33)/$O$28 -> #DIV/0!
B41: =B25 -> 0 | C41: =(S$5*$C$24+S$6*$C$25+S$7*$C$26+S$8*$C$27+S$9*$C$28+S$10*$C$29+S$11*$C$30+S$12*$C$31+S$13*$C$32+S$14*$C$33)/$O$23 -> #DIV/0! | D41: =D25 -> 0 | E41: =(S$5*$E$24+S$6*$E$25+S$7*$E$26+S$8*$E$27+S$9*$E$28+S$10*$E$29+S$11*$E$30+S$12*$E$31+S$13*$E$32+S$14*$E$33)/$O$24 -> #DIV/0! | F41: =F25 -> 0 | G41: =(S$5*$G$24+S$6*$G$25+S$7*$G$26+S$8*$G$27+S$9*$G$28+S$10*$G$29+S$11*$G$30+S$12*$G$31+S$13*$G$32+S$14*$G$33)/$O$25 -> #DIV/0! | H41: =H25 -> 0 | I41: =(S$5*$I$24+S$6*$I$25+S$7*$I$26+S$8*$I$27+S$9*$I$28+S$10*$I$29+S$11*$I$30+S$12*$I$31+S$13*$I$32+S$14*$I$33)/$O$26 -> #DIV/0! | J41: =J25 -> 0 | K41: =(S$5*$K$24+S$6*$K$25+S$7*$K$26+S$8*$K$27+S$9*$K$28+S$10*$K$29+S$11*$K$30+S$12*$K$31+S$13*$K$32+S$14*$K$33)/$O$27 -> #DIV/0! | L41: =L25 -> 0 | M41: =(S$5*$M$24+S$6*$M$25+S$7*$M$26+S$8*$M$27+S$9*$M$28+S$10*$M$29+S$11*$M$30+S$12*$M$31+S$13*$M$32+S$14*$M$33)/$O$28 -> #DIV/0!
B42: =B26 -> 0 | C42: =(T$5*$C$24+T$6*$C$25+T$7*$C$26+T$8*$C$27+T$9*$C$28+T$10*$C$29+T$11*$C$30+T$12*$C$31+T$13*$C$32+T$14*$C$33)/$O$23 -> #DIV/0! | D42: =D26 -> 0 | E42: =(T$5*$E$24+T$6*$E$25+T$7*$E$26+T$8*$E$27+T$9*$E$28+T$10*$E$29+T$11*$E$30+T$12*$E$31+T$13*$E$32+T$14*$E$33)/$O$24 -> #DIV/0! | F42: =F26 -> 0 | G42: =(T$5*$G$24+T$6*$G$25+T$7*$G$26+T$8*$G$27+T$9*$G$28+T$10*$G$29+T$11*$G$30+T$12*$G$31+T$13*$G$32+T$14*$G$33)/$O$25 -> #DIV/0! | H42: =H26 -> 0 | I42: =(T$5*$I$24+T$6*$I$25+T$7*$I$26+T$8*$I$27+T$9*$I$28+T$10*$I$29+T$11*$I$30+T$12*$I$31+T$13*$I$32+T$14*$I$33)/$O$26 -> #DIV/0! | J42: =J26 -> 0 | K42: =(T$5*$K$24+T$6*$K$25+T$7*$K$26+T$8*$K$27+T$9*$K$28+T$10*$K$29+T$11*$K$30+T$12*$K$31+T$13*$K$32+T$14*$K$33)/$O$27 -> #DIV/0! | L42: =L26 -> 0 | M42: =(T$5*$M$24+T$6*$M$25+T$7*$M$26+T$8*$M$27+T$9*$M$28+T$10*$M$29+T$11*$M$30+T$12*$M$31+T$13*$M$32+T$14*$M$33)/$O$28 -> #DIV/0!
B43: =B27 -> 0 | C43: =(U$5*$C$24+U$6*$C$25+U$7*$C$26+U$8*$C$27+U$9*$C$28+U$10*$C$29+U$11*$C$30+U$12*$C$31+U$13*$C$32+U$14*$C$33)/$O$23 -> #DIV/0! | D43: =D27 -> 0 | E43: =(U$5*$E$24+U$6*$E$25+U$7*$E$26+U$8*$E$27+U$9*$E$28+U$10*$E$29+U$11*$E$30+U$12*$E$31+U$13*$E$32+U$14*$E$33)/$O$24 -> #DIV/0! | F43: =F27 -> 0 | G43: =(U$5*$G$24+U$6*$G$25+U$7*$G$26+U$8*$G$27+U$9*$G$28+U$10*$G$29+U$11*$G$30+U$12*$G$31+U$13*$G$32+U$14*$G$33)/$O$25 -> #DIV/0! | H43: =H27 -> 0 | I43: =(U$5*$I$24+U$6*$I$25+U$7*$I$26+U$8*$I$27+U$9*$I$28+U$10*$I$29+U$11*$I$30+U$12*$I$31+U$13*$I$32+U$14*$I$33)/$O$26 -> #DIV/0! | J43: =J27 -> 0 | K43: =(U$5*$K$24+U$6*$K$25+U$7*$K$26+U$8*$K$27+U$9*$K$28+U$10*$K$29+U$11*$K$30+U$12*$K$31+U$13*$K$32+U$14*$K$33)/$O$27 -> #DIV/0! | L43: =L27 -> 0 | M43: =(U$5*$M$24+U$6*$M$25+U$7*$M$26+U$8*$M$27+U$9*$M$28+U$10*$M$29+U$11*$M$30+U$12*$M$31+U$13*$M$32+U$14*$M$33)/$O$28 -> #DIV/0!
B44: =B28 -> 0 | C44: =(V$5*$C$24+V$6*$C$25+V$7*$C$26+V$8*$C$27+V$9*$C$28+V$10*$C$29+V$11*$C$30+V$12*$C$31+V$13*$C$32+V$14*$C$33)/$O$23 -> #DIV/0! | D44: =D28 -> 0 | E44: =(V$5*$E$24+V$6*$E$25+V$7*$E$26+V$8*$E$27+V$9*$E$28+V$10*$E$29+V$11*$E$30+V$12*$E$31+V$13*$E$32+V$14*$E$33)/$O$24 -> #DIV/0! | F44: =F28 -> 0 | G44: =(V$5*$G$24+V$6*$G$25+V$7*$G$26+V$8*$G$27+V$9*$G$28+V$10*$G$29+V$11*$G$30+V$12*$G$31+V$13*$G$32+V$14*$G$33)/$O$25 -> #DIV/0! | H44: =H28 -> 0 | I44: =(V$5*$I$24+V$6*$I$25+V$7*$I$26+V$8*$I$27+V$9*$I$28+V$10*$I$29+V$11*$I$30+V$12*$I$31+V$13*$I$32+V$14*$I$33)/$O$26 -> #DIV/0! | J44: =J28 -> 0 | K44: =(V$5*$K$24+V$6*$K$25+V$7*$K$26+V$8*$K$27+V$9*$K$28+V$10*$K$29+V$11*$K$30+V$12*$K$31+V$13*$K$32+V$14*$K$33)/$O$27 -> #DIV/0! | L44: =L28 -> 0 | M44: =(V$5*$M$24+V$6*$M$25+V$7*$M$26+V$8*$M$27+V$9*$M$28+V$10*$M$29+V$11*$M$30+V$12*$M$31+V$13*$M$32+V$14*$M$33)/$O$28 -> #DIV/0!
B45: =B29 -> 0 | C45: =(W$5*$C$24+W$6*$C$25+W$7*$C$26+W$8*$C$27+W$9*$C$28+W$10*$C$29+W$11*$C$30+W$12*$C$31+W$13*$C$32+W$14*$C$33)/$O$23 -> #DIV/0! | D45: =D29 -> 0 | E45: =(W$5*$E$24+W$6*$E$25+W$7*$E$26+W$8*$E$27+W$9*$E$28+W$10*$E$29+W$11*$E$30+W$12*$E$31+W$13*$E$32+W$14*$E$33)/$O$24 -> #DIV/0! | F45: =F29 -> 0 | G45: =(W$5*$G$24+W$6*$G$25+W$7*$G$26+W$8*$G$27+W$9*$G$28+W$10*$G$29+W$11*$G$30+W$12*$G$31+W$13*$G$32+W$14*$G$33)/$O$25 -> #DIV/0! | H45: =H29 -> 0 | I45: =(W$5*$I$24+W$6*$I$25+W$7*$I$26+W$8*$I$27+W$9*$I$28+W$10*$I$29+W$11*$I$30+W$12*$I$31+W$13*$I$32+W$14*$I$33)/$O$26 -> #DIV/0! | J45: =J29 -> 0 | K45: =(W$5*$K$24+W$6*$K$25+W$7*$K$26+W$8*$K$27+W$9*$K$28+W$10*$K$29+W$11*$K$30+W$12*$K$31+W$13*$K$32+W$14*$K$33)/$O$27 -> #DIV/0! | L45: =L29 -> 0 | M45: =(W$5*$M$24+W$6*$M$25+W$7*$M$26+W$8*$M$27+W$9*$M$28+W$10*$M$29+W$11*$M$30+W$12*$M$31+W$13*$M$32+W$14*$M$33)/$O$28 -> #DIV/0!
B46: =B30 -> 0 | C46: =(X$5*$C$24+X$6*$C$25+X$7*$C$26+X$8*$C$27+X$9*$C$28+X$10*$C$29+X$11*$C$30+X$12*$C$31+X$13*$C$32+X$14*$C$33)/$O$23 -> #DIV/0! | D46: =D30 -> 0 | E46: =(X$5*$E$24+X$6*$E$25+X$7*$E$26+X$8*$E$27+X$9*$E$28+X$10*$E$29+X$11*$E$30+X$12*$E$31+X$13*$E$32+X$14*$E$33)/$O$24 -> #DIV/0! | F46: =F30 -> 0 | G46: =(X$5*$G$24+X$6*$G$25+X$7*$G$26+X$8*$G$27+X$9*$G$28+X$10*$G$29+X$11*$G$30+X$12*$G$31+X$13*$G$32+X$14*$G$33)/$O$25 -> #DIV/0! | H46: =H30 -> 0 | I46: =(X$5*$I$24+X$6*$I$25+X$7*$I$26+X$8*$I$27+X$9*$I$28+X$10*$I$29+X$11*$I$30+X$12*$I$31+X$13*$I$32+X$14*$I$33)/$O$26 -> #DIV/0! | J46: =J30 -> 0 | K46: =(X$5*$K$24+X$6*$K$25+X$7*$K$26+X$8*$K$27+X$9*$K$28+X$10*$K$29+X$11*$K$30+X$12*$K$31+X$13*$K$32+X$14*$K$33)/$O$27 -> #DIV/0! | L46: =L30 -> 0 | M46: =(X$5*$M$24+X$6*$M$25+X$7*$M$26+X$8*$M$27+X$9*$M$28+X$10*$M$29+X$11*$M$30+X$12*$M$31+X$13*$M$32+X$14*$M$33)/$O$28 -> #DIV/0!
...

Sheet boltzmann_plot 
I1: Atoms concentrations
B2: 465.1119 | C2: 510.5537 | D2: 515.323 | E2: 521.8197 | F2: 570.0237 | G2: 578.2127 | K2: λ, nm | L2: =B2*0.000000001 -> 4.651119e-07 | M2: =C2*0.000000001 -> 5.105537e-07 | N2: =D2*0.000000001 -> 5.15323e-07 | O2: =E2*0.000000001 -> 5.218197e-07 | P2: =F2*0.000000001 -> 5.700237e-07 | Q2: =G2*0.000000001 -> 5.782127e-07 | S2: c= | T2: 300000000
B3: 7.737547 | C3: 3.816948 | D3: 6.191593 | E3: 6.192444 | F3: 3.816948 | G3: 3.78615 | K3: Ek, J | L3: =B3*1.6E-19 -> 1.2380075e-18 | M3: =C3*1.6E-19 -> 6.1071168e-19 | N3: =D3*1.6E-19 -> 9.9065488e-19 | O3: =E3*1.6E-19 -> 9.9079104e-19 | P3: =F3*1.6E-19 -> 6.1071168e-19 | Q3: =G3*1.6E-19 -> 6.05784e-19 | S3: h, J*s= | T3: 6.63e-34
B4: 1.4217765 | C4: 0.0197 | D4: 1.64659 | E4: 1.9716688 | F4: 0.0056505367 | G4: 0.013 | K4: Agk, 1/S | L4: =66700000000000*B4/B2/B2 -> 4.3837145e+08 | M4: =66700000000000*C4/C2/C2 -> 5040913 | N4: =66700000000000*D4/D2/D2 -> 4.1357307e+08 | O4: =66700000000000*E4/E2/E2 -> 4.8296855e+08 | P4: =66700000000000*F4/F2/F2 -> 1159924.5 | Q4: =66700000000000*G4/G2/G2 -> 2593545.9 | S4: k, J/K= | T4: 1.38e-23
J5: Σ | K5: r, mm | L5: n_4651 | M5: n_5105 | N5: n_5153 | O5: n_5218 | P5: n_5700 | Q5: n_5782
A6: ='Lines by Gauss'!B56 -> 0 | B6: ='Lines by Gauss'!C56 -> 0 | C6: ='Lines by Gauss'!D56 -> 12353.076 | D6: ='Lines by Gauss'!E56 -> 12353.076 | E6: ='Lines by Gauss'!F56 -> 7807.8814 | F6: ='Lines by Gauss'!G56 -> 0 | G6: ='Lines by Gauss'!H56 -> 5237.9954 | J6: =VLOOKUP($K19,'Partition function'!$A:$B,2,FALSE) -> #DIV/0! | K6: =A6 -> 0 | L6: =1/L$4/$T$2/$T$3*B6*$J6*L$2*EXP(L$3/$T$4/$K19) -> #DIV/0! | M6: =1/M$4/$T$2/$T$3*C6*$J6*M$2*EXP(M$3/$T$4/$K19) -> #DIV/0! | N6: =1/N$4/$T$2/$T$3*D6*$J6*N$2*EXP(N$3/$T$4/$K19) -> #DIV/0! | O6: =1/O$4/$T$2/$T$3*E6*$J6*O$2*EXP(O$3/$T$4/$K19) -> #DIV/0! | P6: =1/P$4/$T$2/$T$3*F6*$J6*P$2*EXP(P$3/$T$4/$K19) -> #DIV/0! | Q6: =1/Q$4/$T$2/$T$3*G6*$J6*Q$2*EXP(Q$3/$T$4/$K19) -> #DIV/0!
A7: ='Lines by Gauss'!B57 -> 0.31861111 | B7: ='Lines by Gauss'!C57 -> 0 | C7: ='Lines by Gauss'!D57 -> 12098.491 | D7: ='Lines by Gauss'!E57 -> 12098.491 | E7: ='Lines by Gauss'!F57 -> 7651.696 | F7: ='Lines by Gauss'!G57 -> 0 | G7: ='Lines by Gauss'!H57 -> 5135.787 | J7: =VLOOKUP($K20,'Partition function'!$A:$B,2,FALSE) -> #DIV/0! | K7: =A7 -> 0.31861111 | L7: =1/L$4/$T$2/$T$3*B7*$J7*L$2*EXP(L$3/$T$4/$K20) -> #DIV/0! | M7: =1/M$4/$T$2/$T$3*C7*$J7*M$2*EXP(M$3/$T$4/$K20) -> #DIV/0! | N7: =1/N$4/$T$2/$T$3*D7*$J7*N$2*EXP(N$3/$T$4/$K20) -> #DIV/0! | O7: =1/O$4/$T$2/$T$3*E7*$J7*O$2*EXP(O$3/$T$4/$K20) -> #DIV/0! | P7: =1/P$4/$T$2/$T$3*F7*$J7*P$2*EXP(P$3/$T$4/$K20) -> #DIV/0! | Q7: =1/Q$4/$T$2/$T$3*G7*$J7*Q$2*EXP(Q$3/$T$4/$K20) -> #DIV/0!
A8: ='Lines by Gauss'!B58 -> 0.63722222 | B8: ='Lines by Gauss'!C58 -> 0 | C8: ='Lines by Gauss'!D58 -> 11356.228 | D8: ='Lines by Gauss'!E58 -> 11356.228 | E8: ='Lines by Gauss'!F58 -> 6863.1805 | F8: ='Lines by Gauss'!G58 -> 0 | G8: ='Lines by Gauss'!H58 -> 4840.4048 | J8: =VLOOKUP($K21,'Partition function'!$A:$B,2,FALSE) -> #DIV/0! | K8: =A8 -> 0.63722222 | L8: =1/L$4/$T$2/$T$3*B8*$J8*L$2*EXP(L$3/$T$4/$K21) -> #DIV/0! | M8: =1/M$4/$T$2/$T$3*C8*$J8*M$2*EXP(M$3/$T$4/$K21) -> #DIV/0! | N8: =1/N$4/$T$2/$T$3*D8*$J8*N$2*EXP(N$3/$T$4/$K21) -> #DIV/0! | O8: =1/O$4/$T$2/$T$3*E8*$J8*O$2*EXP(O$3/$T$4/$K21) -> #DIV/0! | P8: =1/P$4/$T$2/$T$3*F8*$J8*P$2*EXP(P$3/$T$4/$K21) -> #DIV/0! | Q8: =1/Q$4/$T$2/$T$3*G8*$J8*Q$2*EXP(Q$3/$T$4/$K21) -> #DIV/0!
A9: ='Lines by Gauss'!B59 -> 0.95583333 | B9: ='Lines by Gauss'!C59 -> 0 | C9: ='Lines by Gauss'!D59 -> 10198.258 | D9: ='Lines by Gauss'!E59 -> 10198.258 | E9: ='Lines by Gauss'!F59 -> 5910.4367 | F9: ='Lines by Gauss'!G59 -> 0 | G9: ='Lines by Gauss'!H59 -> 4386.5534 | J9: =VLOOKUP($K22,'Partition function'!$A:$B,2,FALSE) -> #DIV/0! | K9: =A9 -> 0.95583333 | L9: =1/L$4/$T$2/$T$3*B9*$J9*L$2*EXP(L$3/$T$4/$K22) -> #DIV/0! | M9: =1/M$4/$T$2/$T$3*C9*$J9*M$2*EXP(M$3/$T$4/$K22) -> #DIV/0! | N9: =1/N$4/$T$2/$T$3*D9*$J9*N$2*EXP(N$3/$T$4/$K22) -> #DIV/0! | O9: =1/O$4/$T$2/$T$3*E9*$J9*O$2*EXP(O$3/$T$4/$K22) -> #DIV/0! | P9: =1/P$4/$T$2/$T$3*F9*$J9*P$2*EXP(P$3/$T$4/$K22) -> #DIV/0! | Q9: =1/Q$4/$T$2/$T$3*G9*$J9*Q$2*EXP(Q$3/$T$4/$K22) -> #DIV/0!
A10: ='Lines by Gauss'!B60 -> 1.2744444 | B10: ='Lines by Gauss'!C60 -> 0 | C10: ='Lines by Gauss'!D60 -> 8812.4426 | D10: ='Lines by Gauss'!E60 -> 8812.4426 | E10: ='Lines by Gauss'!F60 -> 4653.3883 | F10: ='Lines by Gauss'!G60 -> 0 | G10: ='Lines by Gauss'!H60 -> 3820.7387 | J10: =VLOOKUP($K23,'Partition function'!$A:$B,2,FALSE) -> #DIV/0! | K10: =A10 -> 1.2744444 | L10: =1/L$4/$T$2/$T$3*B10*$J10*L$2*EXP(L$3/$T$4/$K23) -> #DIV/0! | M10: =1/M$4/$T$2/$T$3*C10*$J10*M$2*EXP(M$3/$T$4/$K23) -> #DIV/0! | N10: =1/N$4/$T$2/$T$3*D10*$J10*N$2*EXP(N$3/$T$4/$K23) -> #DIV/0! | O10: =1/O$4/$T$2/$T$3*E10*$J10*O$2*EXP(O$3/$T$4/$K23) -> #DIV/0! | P10: =1/P$4/$T$2/$T$3*F10*$J10*P$2*EXP(P$3/$T$4/$K23) -> #DIV/0! | Q10: =1/Q$4/$T$2/$T$3*G10*$J10*Q$2*EXP(Q$3/$T$4/$K23) -> #DIV/0!
A11: ='Lines by Gauss'!B61 -> 1.5930556 | B11: ='Lines by Gauss'!C61 -> 0 | C11: ='Lines by Gauss'!D61 -> 7291.2321 | D11: ='Lines by Gauss'!E61 -> 7291.2321 | E11: ='Lines by Gauss'!F61 -> 3523.329 | F11: ='Lines by Gauss'!G61 -> 0 | G11: ='Lines by Gauss'!H61 -> 3205.2006 | J11: =VLOOKUP($K24,'Partition function'!$A:$B,2,FALSE) -> #DIV/0! | K11: =A11 -> 1.5930556 | L11: =1/L$4/$T$2/$T$3*B11*$J11*L$2*EXP(L$3/$T$4/$K24) -> #DIV/0! | M11: =1/M$4/$T$2/$T$3*C11*$J11*M$2*EXP(M$3/$T$4/$K24) -> #DIV/0! | N11: =1/N$4/$T$2/$T$3*D11*$J11*N$2*EXP(N$3/$T$4/$K24) -> #DIV/0! | O11: =1/O$4/$T$2/$T$3*E11*$J11*O$2*EXP(O$3/$T$4/$K24) -> #DIV/0! | P11: =1/P$4/$T$2/$T$3*F11*$J11*P$2*EXP(P$3/$T$4/$K24) -> #DIV/0! | Q11: =1/Q$4/$T$2/$T$3*G11*$J11*Q$2*EXP(Q$3/$T$4/$K24) -> #DIV/0!
A12: ='Lines by Gauss'!B62 -> 1.9116667 | B12: ='Lines by Gauss'!C62 -> 0 | C12: ='Lines by Gauss'!D62 -> 5809.9199 | D12: ='Lines by Gauss'!E62 -> 5809.9199 | E12: ='Lines by Gauss'!F62 -> 2445.2533 | F12: ='Lines by Gauss'!G62 -> 0 | G12: ='Lines by Gauss'!H62 -> 2595.5991 | J12: =VLOOKUP($K25,'Partition function'!$A:$B,2,FALSE) -> #DIV/0! | K12: =A12 -> 1.9116667 | L12: =1/L$4/$T$2/$T$3*B12*$J12*L$2*EXP(L$3/$T$4/$K25) -> #DIV/0! | M12: =1/M$4/$T$2/$T$3*C12*$J12*M$2*EXP(M$3/$T$4/$K25) -> #DIV/0! | N12: =1/N$4/$T$2/$T$3*D12*$J12*N$2*EXP(N$3/$T$4/$K25) -> #DIV/0! | O12: =1/O$4/$T$2/$T$3*E12*$J12*O$2*EXP(O$3/$T$4/$K25) -> #DIV/0! | P12: =1/P$4/$T$2/$T$3*F12*$J12*P$2*EXP(P$3/$T$4/$K25) -> #DIV/0! | Q12: =1/Q$4/$T$2/$T$3*G12*$J12*Q$2*EXP(Q$3/$T$4/$K25) -> #DIV/0!
A13: ='Lines by Gauss'!B63 -> 2.2302778 | B13: ='Lines by Gauss'!C63 -> 0 | C13: ='Lines by Gauss'!D63 -> 4409.3071 | D13: ='Lines by Gauss'!E63 -> 4409.3071 | E13: ='Lines by Gauss'!F63 -> 1638.3998 | F13: ='Lines by Gauss'!G63 -> 0 | G13: ='Lines by Gauss'!H63 -> 2033.1804 | J13: =VLOOKUP($K26,'Partition function'!$A:$B,2,FALSE) -> #DIV/0! | K13: =A13 -> 2.2302778 | L13: =1/L$4/$T$2/$T$3*B13*$J13*L$2*EXP(L$3/$T$4/$K26) -> #DIV/0! | M13: =1/M$4/$T$2/$T$3*C13*$J13*M$2*EXP(M$3/$T$4/$K26) -> #DIV/0! | N13: =1/N$4/$T$2/$T$3*D13*$J13*N$2*EXP(N$3/$T$4/$K26) -> #DIV/0! | O13: =1/O$4/$T$2/$T$3*E13*$J13*O$2*EXP(O$3/$T$4/$K26) -> #DIV/0! | P13: =1/P$4/$T$2/$T$3*F13*$J13*P$2*EXP(P$3/$T$4/$K26) -> #DIV/0! | Q13: =1/Q$4/$T$2/$T$3*G13*$J13*Q$2*EXP(Q$3/$T$4/$K26) -> #DIV/0!
A14: ='Lines by Gauss'!B64 -> 2.5488889 | B14: ='Lines by Gauss'!C64 -> 0 | C14: ='Lines by Gauss'!D64 -> 3233.426 | D14: ='Lines by Gauss'!E64 -> 3233.426 | E14: ='Lines by Gauss'!F64 -> 1019.5968 | F14: ='Lines by Gauss'!G64 -> 0 | G14: ='Lines by Gauss'!H64 -> 1527.4416 | J14: =VLOOKUP($K27,'Partition function'!$A:$B,2,FALSE) -> #DIV/0! | K14: =A14 -> 2.5488889 | L14: =1/L$4/$T$2/$T$3*B14*$J14*L$2*EXP(L$3/$T$4/$K27) -> #DIV/0! | M14: =1/M$4/$T$2/$T$3*C14*$J14*M$2*EXP(M$3/$T$4/$K27) -> #DIV/0! | N14: =1/N$4/$T$2/$T$3*D14*$J14*N$2*EXP(N$3/$T$4/$K27) -> #DIV/0! | O14: =1/O$4/$T$2/$T$3*E14*$J14*O$2*EXP(O$3/$T$4/$K27) -> #DIV/0! | P14: =1/P$4/$T$2/$T$3*F14*$J14*P$2*EXP(P$3/$T$4/$K27) -> #DIV/0! | Q14: =1/Q$4/$T$2/$T$3*G14*$J14*Q$2*EXP(Q$3/$T$4/$K27) -> #DIV/0!
A15: ='Lines by Gauss'!B65 -> 2.8675 | B15: ='Lines by Gauss'!C65 -> 0 | C15: ='Lines by Gauss'!D65 -> 2281.1893 | D15: ='Lines by Gauss'!E65 -> 2281.1893 | E15: ='Lines by Gauss'!F65 -> 792.32501 | F15: ='Lines by Gauss'!G65 -> 0 | G15: ='Lines by Gauss'!H65 -> 1195.6114 | J15: =VLOOKUP($K28,'Partition function'!$A:$B,2,FALSE) -> #DIV/0! | K15: =A15 -> 2.8675 | L15: =1/L$4/$T$2/$T$3*B15*$J15*L$2*EXP(L$3/$T$4/$K28) -> #DIV/0! | M15: =1/M$4/$T$2/$T$3*C15*$J15*M$2*EXP(M$3/$T$4/$K28) -> #DIV/0! | N15: =1/N$4/$T$2/$T$3*D15*$J15*N$2*EXP(N$3/$T$4/$K28) -> #DIV/0! | O15: =1/O$4/$T$2/$T$3*E15*$J15*O$2*EXP(O$3/$T$4/$K28) -> #DIV/0! | P15: =1/P$4/$T$2/$T$3*F15*$J15*P$2*EXP(P$3/$T$4/$K28) -> #DIV/0! | Q15: =1/Q$4/$T$2/$T$3*G15*$J15*Q$2*EXP(Q$3/$T$4/$K28) -> #DIV/0!
J18: r, mm | K18: T, K | L18: dT, K | M18: a | N18: da | P18: b | Q18: db | S18: n, m-3 | T18: dn, m-3
A19: =A6 -> 0 | B19: =LN(B6*B$2^3/B$4) -> #NUM! | C19: =LN(C6*C$2^3/C$4) -> 32.055284 | D19: =LN(D6*D$2^3/D$4) -> 27.657336 | E19: =LN(E6*E$2^3/E$4) -> 27.055975 | F19: =LN(F6*F$2^3/F$4) -> #NUM! | G19: =LN(G6*G$2^3/G$4) -> 31.986325 | J19: =A6 -> 0 | K19: =ROUND(-11600/M19,0) -> #DIV/0! | L19: =ROUND(-K19*N19/M19,0) -> #DIV/0! | M19: =W20 -> 0 | N19: =X20 -> 0 | P19: =W19 -> 0 | Q19: =X19 -> 0 | S19: =EXP(P19)*J6/66700000000000/$T$3/$T$2*0.000000001 -> #DIV/0! | T19: =Q19*S19/P19 -> #DIV/0! | V19: b1
A20: =A7 -> 0.31861111 | B20: =LN(B7*B$2^3/B$4) -> #NUM! | C20: =LN(C7*C$2^3/C$4) -> 32.03446 | D20: =LN(D7*D$2^3/D$4) -> 27.636511 | E20: =LN(E7*E$2^3/E$4) -> 27.035769 | F20: =LN(F7*F$2^3/F$4) -> #NUM! | G20: =LN(G7*G$2^3/G$4) -> 31.96662 | J20: =A7 -> 0.31861111 | K20: =ROUND(-11600/M20,0) -> #DIV/0! | L20: =ROUND(-K20*N20/M20,0) -> #DIV/0! | M20: =W22 -> 0 | N20: =X22 -> 0 | P20: =W21 -> 0 | Q20: =X21 -> 0 | S20: =EXP(P20)*J7/66700000000000/$T$3/$T$2*0.000000001 -> #DIV/0! | T20: =Q20*S20/P20 -> #DIV/0! | V20: a1
A21: =A8 -> 0.63722222 | B21: =LN(B8*B$2^3/B$4) -> #NUM! | C21: =LN(C8*C$2^3/C$4) -> 31.971146 | D21: =LN(D8*D$2^3/D$4) -> 27.573197 | E21: =LN(E8*E$2^3/E$4) -> 26.927012 | F21: =LN(F8*F$2^3/F$4) -> #NUM! | G21: =LN(G8*G$2^3/G$4) -> 31.907385 | J21: =A8 -> 0.63722222 | K21: =ROUND(-11600/M21,0) -> #DIV/0! | L21: =ROUND(-K21*N21/M21,0) -> #DIV/0! | M21: =W24 -> 0 | N21: =X24 -> 0 | P21: =W23 -> 0 | Q21: =X23 -> 0 | S21: =EXP(P21)*J8/66700000000000/$T$3/$T$2*0.000000001 -> #DIV/0! | T21: =Q21*S21/P21 -> #DIV/0! | V21: b2
A22: =A9 -> 0.95583333 | B22: =LN(B9*B$2^3/B$4) -> #NUM! | C22: =LN(C9*C$2^3/C$4) -> 31.863596 | D22: =LN(D9*D$2^3/D$4) -> 27.465647 | E22: =LN(E9*E$2^3/E$4) -> 26.777561 | F22: =LN(F9*F$2^3/F$4) -> #NUM! | G22: =LN(G9*G$2^3/G$4) -> 31.80893 | J22: =A9 -> 0.95583333 | K22: =ROUND(-11600/M22,0) -> #DIV/0! | L22: =ROUND(-K22*N22/M22,0) -> #DIV/0! | M22: =W26 -> 0 | N22: =X26 -> 0 | P22: =W25 -> 0 | Q22: =X25 -> 0 | S22: =EXP(P22)*J9/66700000000000/$T$3/$T$2*0.000000001 -> #DIV/0! | T22: =Q22*S22/P22 -> #DIV/0! | V22: a2
A23: =A10 -> 1.2744444 | B23: =LN(B10*B$2^3/B$4) -> #NUM! | C23: =LN(C10*C$2^3/C$4) -> 31.717544 | D23: =LN(D10*D$2^3/D$4) -> 27.319595 | E23: =LN(E10*E$2^3/E$4) -> 26.538437 | F23: =LN(F10*F$2^3/F$4) -> #NUM! | G23: =LN(G10*G$2^3/G$4) -> 31.67083 | J23: =A10 -> 1.2744444 | K23: =ROUND(-11600/M23,0) -> #DIV/0! | L23: =ROUND(-K23*N23/M23,0) -> #DIV/0! | M23: =W28 -> 0 | N23: =X28 -> 0 | P23: =W27 -> 0 | Q23: =X27 -> 0 | S23: =EXP(P23)*J10/66700000000000/$T$3/$T$2*0.000000001 -> #DIV/0! | T23: =Q23*S23/P23 -> #DIV/0! | V23: b3
A24: =A11 -> 1.5930556 | B24: =LN(B11*B$2^3/B$4) -> #NUM! | C24: =LN(C11*C$2^3/C$4) -> 31.528052 | D24: =LN(D11*D$2^3/D$4) -> 27.130103 | E24: =LN(E11*E$2^3/E$4) -> 26.260248 | F24: =LN(F11*F$2^3/F$4) -> #NUM! | G24: =LN(G11*G$2^3/G$4) -> 31.495161 | J24: =A11 -> 1.5930556 | K24: =ROUND(-11600/M24,0) -> #DIV/0! | L24: =ROUND(-K24*N24/M24,0) -> #DIV/0! | M24: =W30 -> 0 | N24: =X30 -> 0 | P24: =W29 -> 0 | Q24: =X29 -> 0 | S24: =EXP(P24)*J11/66700000000000/$T$3/$T$2*0.000000001 -> #DIV/0! | T24: =Q24*S24/P24 -> #DIV/0! | V24: a3
A25: =A12 -> 1.9116667 | B25: =LN(B12*B$2^3/B$4) -> #NUM! | C25: =LN(C12*C$2^3/C$4) -> 31.300946 | D25: =LN(D12*D$2^3/D$4) -> 26.902997 | E25: =LN(E12*E$2^3/E$4) -> 25.89499 | F25: =LN(F12*F$2^3/F$4) -> #NUM! | G25: =LN(G12*G$2^3/G$4) -> 31.284204 | J25: =A12 -> 1.9116667 | K25: =ROUND(-11600/M25,0) -> #DIV/0! | L25: =ROUND(-K25*N25/M25,0) -> #DIV/0! | M25: =W32 -> 0 | N25: =X32 -> 0 | P25: =W31 -> 0 | Q25: =X31 -> 0 | S25: =EXP(P25)*J12/66700000000000/$T$3/$T$2*0.000000001 -> #DIV/0! | T25: =Q25*S25/P25 -> #DIV/0! | V25: b4
A26: =A13 -> 2.2302778 | B26: =LN(B13*B$2^3/B$4) -> #NUM! | C26: =LN(C13*C$2^3/C$4) -> 31.025097 | D26: =LN(D13*D$2^3/D$4) -> 26.627148 | E26: =LN(E13*E$2^3/E$4) -> 25.494561 | F26: =LN(F13*F$2^3/F$4) -> #NUM! | G26: =LN(G13*G$2^3/G$4) -> 31.039988 | J26: =A13 -> 2.2302778 | K26: =ROUND(-11600/M26,0) -> #DIV/0! | L26: =ROUND(-K26*N26/M26,0) -> #DIV/0! | M26: =W34 -> 0 | N26: =X34 -> 0 | P26: =W33 -> 0 | Q26: =X33 -> 0 | S26: =EXP(P26)*J13/66700000000000/$T$3/$T$2*0.000000001 -> #DIV/0! | T26: =Q26*S26/P26 -> #DIV/0! | V26: a4
A27: =A14 -> 2.5488889 | B27: =LN(B14*B$2^3/B$4) -> #NUM! | C27: =LN(C14*C$2^3/C$4) -> 30.714922 | D27: =LN(D14*D$2^3/D$4) -> 26.316973 | E27: =LN(E14*E$2^3/E$4) -> 25.020249 | F27: =LN(F14*F$2^3/F$4) -> #NUM! | G27: =LN(G14*G$2^3/G$4) -> 30.753981 | J27: =A14 -> 2.5488889 | K27: =ROUND(-11600/M27,0) -> #DIV/0! | L27: =ROUND(-K27*N27/M27,0) -> #DIV/0! | M27: =W36 -> 0 | N27: =X36 -> 0 | P27: =W35 -> 0 | Q27: =X35 -> 0 | S27: =EXP(P27)*J14/66700000000000/$T$3/$T$2*0.000000001 -> #DIV/0! | T27: =Q27*S27/P27 -> #DIV/0! | V27: b5
A28: =A15 -> 2.8675 | B28: =LN(B15*B$2^3/B$4) -> #NUM! | C28: =LN(C15*C$2^3/C$4) -> 30.366076 | D28: =LN(D15*D$2^3/D$4) -> 25.968127 | E28: =LN(E15*E$2^3/E$4) -> 24.768058 | F28: =LN(F15*F$2^3/F$4) -> #NUM! | G28: =LN(G15*G$2^3/G$4) -> 30.509044 | J28: =A15 -> 2.8675 | K28: =ROUND(-11600/M28,0) -> #DIV/0! | L28: =ROUND(-K28*N28/M28,0) -> #DIV/0! | M28: =W38 -> 0 | N28: =X38 -> 0 | P28: =W37 -> 0 | Q28: =X37 -> 0 | S28: =EXP(P28)*J15/66700000000000/$T$3/$T$2*0.000000001 -> #DIV/0! | T28: =Q28*S28/P28 -> #DIV/0! | V28: a5
V29: b6
V30: a6
A31: Levels populations | V31: b7
A32: λ, nm | B32: =B2*0.000000001 -> 4.651119e-07 | C32: =C2*0.000000001 -> 5.105537e-07 | D32: =D2*0.000000001 -> 5.15323e-07 | E32: =E2*0.000000001 -> 5.218197e-07 | F32: =F2*0.000000001 -> 5.700237e-07 | G32: =G2*0.000000001 -> 5.782127e-07 | V32: a7
A33: Ek, J | B33: 7.737547 | C33: 3.816948 | D33: 6.191593 | E33: 6.192444 | F33: 3.816948 | G33: 3.78615 | V33: b8
A34: gk | B34: 8 | C34: 4 | D34: 4 | E34: 6 | F34: 4 | G34: 2 | V34: a8
A35: A, 1/S | B35: =66700000000000*B4/B2/B2/B34 -> 54796431 | C35: =66700000000000*C4/C2/C2/C34 -> 1260228.3 | D35: =66700000000000*D4/D2/D2/D34 -> 1.0339327e+08 | E35: =66700000000000*E4/E2/E2/E34 -> 80494758 | F35: =66700000000000*F4/F2/F2/F34 -> 289981.11 | G35: =66700000000000*G4/G2/G2/G34 -> 1296772.9 | J35: ln(n_4651) | K35: ln(n_5105) | L35: ln(n_5153) | M35: ln(n_5218) | N35: ln(n_5700) | O35: ln(n_5782) | V35: b9
A36: r, mm | B36: n_4651 | C36: n_5105 | D36: n_5153 | E36: n_5218 | F36: n_5700 | G36: n_5782 | I36: r, mm | J36: 7.737547 | K36: 3.816948 | L36: 6.191593 | M36: 6.192444 | N36: 3.816948 | O36: 3.78615 | V36: a9
A37: =A6 -> 0 | B37: =1/$T$3/$T$2/B$35*B$32*B6 -> 0 | C37: =1/$T$3/$T$2/C$35*C$32*C6 -> 2.5161269e+16 | D37: =1/$T$3/$T$2/D$35*D$32*D6 -> 3.0954771e+14 | E37: =1/$T$3/$T$2/E$35*E$32*E6 -> 2.5447862e+14 | F37: =1/$T$3/$T$2/F$35*F$32*F6 -> 0 | G37: =1/$T$3/$T$2/G$35*G$32*G6 -> 1.1742323e+16 | I37: =A37 -> 0 | J37: =LN(B37/B$34) -> #NUM! | K37: =LN(C37/C$34) -> 36.377788 | L37: =LN(D37/D$34) -> 31.979839 | M37: =LN(E37/E$34) -> 31.378478 | N37: =LN(F37/F$34) -> #NUM! | O37: =LN(G37/G$34) -> 36.308829 | V37: b10
A38: =A7 -> 0.31861111 | B38: =1/$T$3/$T$2/B$35*B$32*B7 -> 0 | C38: =1/$T$3/$T$2/C$35*C$32*C7 -> 2.464272e+16 | D38: =1/$T$3/$T$2/D$35*D$32*D7 -> 303168239937248 | E38: =1/$T$3/$T$2/E$35*E$32*E7 -> 2.4938814e+14 | F38: =1/$T$3/$T$2/F$35*F$32*F7 -> 0 | G38: =1/$T$3/$T$2/G$35*G$32*G7 -> 1.1513196e+16 | I38: =A38 -> 0.31861111 | J38: =LN(B38/B$34) -> #NUM! | K38: =LN(C38/C$34) -> 36.356964 | L38: =LN(D38/D$34) -> 31.959015 | M38: =LN(E38/E$34) -> 31.358272 | N38: =LN(F38/F$34) -> #NUM! | O38: =LN(G38/G$34) -> 36.289123 | V38: a10
A39: =A8 -> 0.63722222 | B39: =1/$T$3/$T$2/B$35*B$32*B8 -> 0 | C39: =1/$T$3/$T$2/C$35*C$32*C8 -> 2.3130847e+16 | D39: =1/$T$3/$T$2/D$35*D$32*D8 -> 2.8456835e+14 | E39: =1/$T$3/$T$2/E$35*E$32*E8 -> 2.2368843e+14 | F39: =1/$T$3/$T$2/F$35*F$32*F8 -> 0 | G39: =1/$T$3/$T$2/G$35*G$32*G8 -> 1.0851021e+16 | I39: =A39 -> 0.63722222 | J39: =LN(B39/B$34) -> #NUM! | K39: =LN(C39/C$34) -> 36.293649 | L39: =LN(D39/D$34) -> 31.8957 | M39: =LN(E39/E$34) -> 31.249516 | N39: =LN(F39/F$34) -> #NUM! | O39: =LN(G39/G$34) -> 36.229888
A40: =A9 -> 0.95583333 | B40: =1/$T$3/$T$2/B$35*B$32*B9 -> 0 | C40: =1/$T$3/$T$2/C$35*C$32*C9 -> 2.0772244e+16 | D40: =1/$T$3/$T$2/D$35*D$32*D9 -> 2.5555153e+14 | E40: =1/$T$3/$T$2/E$35*E$32*E9 -> 1.9263609e+14 | F40: =1/$T$3/$T$2/F$35*F$32*F9 -> 0 | G40: =1/$T$3/$T$2/G$35*G$32*G9 -> 9.8335952e+15 | I40: =A40 -> 0.95583333 | J40: =LN(B40/B$34) -> #NUM! | K40: =LN(C40/C$34) -> 36.1861 | L40: =LN(D40/D$34) -> 31.788151 | M40: =LN(E40/E$34) -> 31.100065 | N40: =LN(F40/F$34) -> #NUM! | O40: =LN(G40/G$34) -> 36.131434
A41: =A10 -> 1.2744444 | B41: =1/$T$3/$T$2/B$35*B$32*B10 -> 0 | C41: =1/$T$3/$T$2/C$35*C$32*C10 -> 1.7949557e+16 | D41: =1/$T$3/$T$2/D$35*D$32*D10 -> 2.2082528e+14 | E41: =1/$T$3/$T$2/E$35*E$32*E10 -> 1.516657e+14 | F41: =1/$T$3/$T$2/F$35*F$32*F10 -> 0 | G41: =1/$T$3/$T$2/G$35*G$32*G10 -> 8.565175e+15 | I41: =A41 -> 1.2744444 | J41: =LN(B41/B$34) -> #NUM! | K41: =LN(C41/C$34) -> 36.040047 | L41: =LN(D41/D$34) -> 31.642099 | M41: =LN(E41/E$34) -> 30.86094 | N41: =LN(F41/F$34) -> #NUM! | O41: =LN(G41/G$34) -> 35.993334
A42: =A11 -> 1.5930556 | B42: =1/$T$3/$T$2/B$35*B$32*B11 -> 0 | C42: =1/$T$3/$T$2/C$35*C$32*C11 -> 1.4851091e+16 | D42: =1/$T$3/$T$2/D$35*D$32*D11 -> 1.8270625e+14 | E42: =1/$T$3/$T$2/E$35*E$32*E11 -> 1.1483421e+14 | F42: =1/$T$3/$T$2/F$35*F$32*F11 -> 0 | G42: =1/$T$3/$T$2/G$35*G$32*G11 -> 7.1852871e+15 | I42: =A42 -> 1.5930556 | J42: =LN(B42/B$34) -> #NUM! | K42: =LN(C42/C$34) -> 35.850555 | L42: =LN(D42/D$34) -> 31.452606 | M42: =LN(E42/E$34) -> 30.582751 | N42: =LN(F42/F$34) -> #NUM! | O42: =LN(G42/G$34) -> 35.817665
...

Sheet Boltzmann_plot_withdrawn
I1: Atoms concentrations
B2: 465.1119 | C2: 510.5537 | D2: 515.323 | E2: 521.8197 | F2: 570.0237 | G2: 578.2127 | K2: λ, nm | L2: =B2*0.000000001 -> 4.651119e-07 | M2: =C2*0.000000001 -> 5.105537e-07 | N2: =D2*0.000000001 -> 5.15323e-07 | O2: =E2*0.000000001 -> 5.218197e-07 | P2: =F2*0.000000001 -> 5.700237e-07 | Q2: =G2*0.000000001 -> 5.782127e-07 | S2: c= | T2: 300000000
B3: 7.737547 | C3: 3.816948 | D3: 6.191593 | E3: 6.192444 | F3: 3.816948 | G3: 3.78615 | K3: Ek, J | L3: =B3*1.6E-19 -> 1.2380075e-18 | M3: =C3*1.6E-19 -> 6.1071168e-19 | N3: =D3*1.6E-19 -> 9.9065488e-19 | O3: =E3*1.6E-19 -> 9.9079104e-19 | P3: =F3*1.6E-19 -> 6.1071168e-19 | Q3: =G3*1.6E-19 -> 6.05784e-19 | S3: h, J*s= | T3: 6.63e-34
B4: 1.4217765 | C4: 0.0197 | D4: 1.64659 | E4: 1.9716688 | F4: 0.0056505367 | G4: 0.013 | K4: Agk, 1/S | L4: =66700000000000*B4/B2/B2 -> 4.3837145e+08 | M4: =66700000000000*C4/C2/C2 -> 5040913 | N4: =66700000000000*D4/D2/D2 -> 4.1357307e+08 | O4: =66700000000000*E4/E2/E2 -> 4.8296855e+08 | P4: =66700000000000*F4/F2/F2 -> 1159924.5 | Q4: =66700000000000*G4/G2/G2 -> 2593545.9 | S4: k, J/K= | T4: 1.38e-23
J5: Σ | K5: r, mm | L5: n_4651 | M5: n_5105 | N5: n_5153 | O5: n_5218 | P5: n_5700 | Q5: n_5782
A6: ='Lines by Gauss'!B56 -> 0 | B6: ='Lines by Gauss'!C56 -> 0 | C6: ='Lines by Gauss'!D56 -> 12353.076 | D6: ='Lines by Gauss'!E56 -> 12353.076 | E6: ='Lines by Gauss'!F56 -> 7807.8814 | F6: ='Lines by Gauss'!G56 -> 0 | G6: ='Lines by Gauss'!H56 -> 5237.9954 | J6: =VLOOKUP($K19,'Partition function'!$A:$B,2,FALSE) -> #DIV/0! | K6: =A6 -> 0 | L6: =1/L$4/$T$2/$T$3*B6*$J6*L$2*EXP(L$3/$T$4/$K19) -> #DIV/0! | M6: =1/M$4/$T$2/$T$3*C6*$J6*M$2*EXP(M$3/$T$4/$K19) -> #DIV/0! | N6: =1/N$4/$T$2/$T$3*D6*$J6*N$2*EXP(N$3/$T$4/$K19) -> #DIV/0! | O6: =1/O$4/$T$2/$T$3*E6*$J6*O$2*EXP(O$3/$T$4/$K19) -> #DIV/0! | P6: =1/P$4/$T$2/$T$3*F6*$J6*P$2*EXP(P$3/$T$4/$K19) -> #DIV/0! | Q6: =1/Q$4/$T$2/$T$3*G6*$J6*Q$2*EXP(Q$3/$T$4/$K19) -> #DIV/0!
A7: ='Lines by Gauss'!B57 -> 0.31861111 | B7: ='Lines by Gauss'!C57 -> 0 | C7: ='Lines by Gauss'!D57 -> 12098.491 | D7: ='Lines by Gauss'!E57 -> 12098.491 | E7: ='Lines by Gauss'!F57 -> 7651.696 | F7: ='Lines by Gauss'!G57 -> 0 | G7: ='Lines by Gauss'!H57 -> 5135.787 | J7: =VLOOKUP($K20,'Partition function'!$A:$B,2,FALSE) -> #DIV/0! | K7: =A7 -> 0.31861111 | L7: =1/L$4/$T$2/$T$3*B7*$J7*L$2*EXP(L$3/$T$4/$K20) -> #DIV/0! | M7: =1/M$4/$T$2/$T$3*C7*$J7*M$2*EXP(M$3/$T$4/$K20) -> #DIV/0! | N7: =1/N$4/$T$2/$T$3*D7*$J7*N$2*EXP(N$3/$T$4/$K20) -> #DIV/0! | O7: =1/O$4/$T$2/$T$3*E7*$J7*O$2*EXP(O$3/$T$4/$K20) -> #DIV/0! | P7: =1/P$4/$T$2/$T$3*F7*$J7*P$2*EXP(P$3/$T$4/$K20) -> #DIV/0! | Q7: =1/Q$4/$T$2/$T$3*G7*$J7*Q$2*EXP(Q$3/$T$4/$K20) -> #DIV/0!
A8: ='Lines by Gauss'!B58 -> 0.63722222 | B8: ='Lines by Gauss'!C58 -> 0 | C8: ='Lines by Gauss'!D58 -> 11356.228 | D8: ='Lines by Gauss'!E58 -> 11356.228 | E8: ='Lines by Gauss'!F58 -> 6863.1805 | F8: ='Lines by Gauss'!G58 -> 0 | G8: ='Lines by Gauss'!H58 -> 4840.4048 | J8: =VLOOKUP($K21,'Partition function'!$A:$B,2,FALSE) -> #DIV/0! | K8: =A8 -> 0.63722222 | L8: =1/L$4/$T$2/$T$3*B8*$J8*L$2*EXP(L$3/$T$4/$K21) -> #DIV/0! | M8: =1/M$4/$T$2/$T$3*C8*$J8*M$2*EXP(M$3/$T$4/$K21) -> #DIV/0! | N8: =1/N$4/$T$2/$T$3*D8*$J8*N$2*EXP(N$3/$T$4/$K21) -> #DIV/0! | O8: =1/O$4/$T$2/$T$3*E8*$J8*O$2*EXP(O$3/$T$4/$K21) -> #DIV/0! | P8: =1/P$4/$T$2/$T$3*F8*$J8*P$2*EXP(P$3/$T$4/$K21) -> #DIV/0! | Q8: =1/Q$4/$T$2/$T$3*G8*$J8*Q$2*EXP(Q$3/$T$4/$K21) -> #DIV/0!
A9: ='Lines by Gauss'!B59 -> 0.95583333 | B9: ='Lines by Gauss'!C59 -> 0 | C9: ='Lines by Gauss'!D59 -> 10198.258 | D9: ='Lines by Gauss'!E59 -> 10198.258 | E9: ='Lines by Gauss'!F59 -> 5910.4367 | F9: ='Lines by Gauss'!G59 -> 0 | G9: ='Lines by Gauss'!H59 -> 4386.5534 | J9: =VLOOKUP($K22,'Partition function'!$A:$B,2,FALSE) -> #DIV/0! | K9: =A9 -> 0.95583333 | L9: =1/L$4/$T$2/$T$3*B9*$J9*L$2*EXP(L$3/$T$4/$K22) -> #DIV/0! | M9: =1/M$4/$T$2/$T$3*C9*$J9*M$2*EXP(M$3/$T$4/$K22) -> #DIV/0! | N9: =1/N$4/$T$2/$T$3*D9*$J9*N$2*EXP(N$3/$T$4/$K22) -> #DIV/0! | O9: =1/O$4/$T$2/$T$3*E9*$J9*O$2*EXP(O$3/$T$4/$K22) -> #DIV/0! | P9: =1/P$4/$T$2/$T$3*F9*$J9*P$2*EXP(P$3/$T$4/$K22) -> #DIV/0! | Q9: =1/Q$4/$T$2/$T$3*G9*$J9*Q$2*EXP(Q$3/$T$4/$K22) -> #DIV/0!
A10: ='Lines by Gauss'!B60 -> 1.2744444 | B10: ='Lines by Gauss'!C60 -> 0 | C10: ='Lines by Gauss'!D60 -> 8812.4426 | D10: ='Lines by Gauss'!E60 -> 8812.4426 | E10: ='Lines by Gauss'!F60 -> 4653.3883 | F10: ='Lines by Gauss'!G60 -> 0 | G10: ='Lines by Gauss'!H60 -> 3820.7387 | J10: =VLOOKUP($K23,'Partition function'!$A:$B,2,FALSE) -> #DIV/0! | K10: =A10 -> 1.2744444 | L10: =1/L$4/$T$2/$T$3*B10*$J10*L$2*EXP(L$3/$T$4/$K23) -> #DIV/0! | M10: =1/M$4/$T$2/$T$3*C10*$J10*M$2*EXP(M$3/$T$4/$K23) -> #DIV/0! | N10: =1/N$4/$T$2/$T$3*D10*$J10*N$2*EXP(N$3/$T$4/$K23) -> #DIV/0! | O10: =1/O$4/$T$2/$T$3*E10*$J10*O$2*EXP(O$3/$T$4/$K23) -> #DIV/0! | P10: =1/P$4/$T$2/$T$3*F10*$J10*P$2*EXP(P$3/$T$4/$K23) -> #DIV/0! | Q10: =1/Q$4/$T$2/$T$3*G10*$J10*Q$2*EXP(Q$3/$T$4/$K23) -> #DIV/0!
A11: ='Lines by Gauss'!B61 -> 1.5930556 | B11: ='Lines by Gauss'!C61 -> 0 | C11: ='Lines by Gauss'!D61 -> 7291.2321 | D11: ='Lines by Gauss'!E61 -> 7291.2321 | E11: ='Lines by Gauss'!F61 -> 3523.329 | F11: ='Lines by Gauss'!G61 -> 0 | G11: ='Lines by Gauss'!H61 -> 3205.2006 | J11: =VLOOKUP($K24,'Partition function'!$A:$B,2,FALSE) -> #DIV/0! | K11: =A11 -> 1.5930556 | L11: =1/L$4/$T$2/$T$3*B11*$J11*L$2*EXP(L$3/$T$4/$K24) -> #DIV/0! | M11: =1/M$4/$T$2/$T$3*C11*$J11*M$2*EXP(M$3/$T$4/$K24) -> #DIV/0! | N11: =1/N$4/$T$2/$T$3*D11*$J11*N$2*EXP(N$3/$T$4/$K24) -> #DIV/0! | O11: =1/O$4/$T$2/$T$3*E11*$J11*O$2*EXP(O$3/$T$4/$K24) -> #DIV/0! | P11: =1/P$4/$T$2/$T$3*F11*$J11*P$2*EXP(P$3/$T$4/$K24) -> #DIV/0! | Q11: =1/Q$4/$T$2/$T$3*G11*$J11*Q$2*EXP(Q$3/$T$4/$K24) -> #DIV/0!
A12: ='Lines by Gauss'!B62 -> 1.9116667 | B12: ='Lines by Gauss'!C62 -> 0 | C12: ='Lines by Gauss'!D62 -> 5809.9199 | D12: ='Lines by Gauss'!E62 -> 5809.9199 | E12: ='Lines by Gauss'!F62 -> 2445.2533 | F12: ='Lines by Gauss'!G62 -> 0 | G12: ='Lines by Gauss'!H62 -> 2595.5991 | J12: =VLOOKUP($K25,'Partition function'!$A:$B,2,FALSE) -> #DIV/0! | K12: =A12 -> 1.9116667 | L12: =1/L$4/$T$2/$T$3*B12*$J12*L$2*EXP(L$3/$T$4/$K25) -> #DIV/0! | M12: =1/M$4/$T$2/$T$3*C12*$J12*M$2*EXP(M$3/$T$4/$K25) -> #DIV/0! | N12: =1/N$4/$T$2/$T$3*D12*$J12*N$2*EXP(N$3/$T$4/$K25) -> #DIV/0! | O12: =1/O$4/$T$2/$T$3*E12*$J12*O$2*EXP(O$3/$T$4/$K25) -> #DIV/0! | P12: =1/P$4/$T$2/$T$3*F12*$J12*P$2*EXP(P$3/$T$4/$K25) -> #DIV/0! | Q12: =1/Q$4/$T$2/$T$3*G12*$J12*Q$2*EXP(Q$3/$T$4/$K25) -> #DIV/0!
A13: ='Lines by Gauss'!B63 -> 2.2302778 | B13: ='Lines by Gauss'!C63 -> 0 | C13: ='Lines by Gauss'!D63 -> 4409.3071 | D13: ='Lines by Gauss'!E63 -> 4409.3071 | E13: ='Lines by Gauss'!F63 -> 1638.3998 | F13: ='Lines by Gauss'!G63 -> 0 | G13: ='Lines by Gauss'!H63 -> 2033.1804 | J13: =VLOOKUP($K26,'Partition function'!$A:$B,2,FALSE) -> #DIV/0! | K13: =A13 -> 2.2302778 | L13: =1/L$4/$T$2/$T$3*B13*$J13*L$2*EXP(L$3/$T$4/$K26) -> #DIV/0! | M13: =1/M$4/$T$2/$T$3*C13*$J13*M$2*EXP(M$3/$T$4/$K26) -> #DIV/0! | N13: =1/N$4/$T$2/$T$3*D13*$J13*N$2*EXP(N$3/$T$4/$K26) -> #DIV/0! | O13: =1/O$4/$T$2/$T$3*E13*$J13*O$2*EXP(O$3/$T$4/$K26) -> #DIV/0! | P13: =1/P$4/$T$2/$T$3*F13*$J13*P$2*EXP(P$3/$T$4/$K26) -> #DIV/0! | Q13: =1/Q$4/$T$2/$T$3*G13*$J13*Q$2*EXP(Q$3/$T$4/$K26) -> #DIV/0!
A14: ='Lines by Gauss'!B64 -> 2.5488889 | B14: ='Lines by Gauss'!C64 -> 0 | C14: ='Lines by Gauss'!D64 -> 3233.426 | D14: ='Lines by Gauss'!E64 -> 3233.426 | E14: ='Lines by Gauss'!F64 -> 1019.5968 | F14: ='Lines by Gauss'!G64 -> 0 | G14: ='Lines by Gauss'!H64 -> 1527.4416 | J14: =VLOOKUP($K27,'Partition function'!$A:$B,2,FALSE) -> #DIV/0! | K14: =A14 -> 2.5488889 | L14: =1/L$4/$T$2/$T$3*B14*$J14*L$2*EXP(L$3/$T$4/$K27) -> #DIV/0! | M14: =1/M$4/$T$2/$T$3*C14*$J14*M$2*EXP(M$3/$T$4/$K27) -> #DIV/0! | N14: =1/N$4/$T$2/$T$3*D14*$J14*N$2*EXP(N$3/$T$4/$K27) -> #DIV/0! | O14: =1/O$4/$T$2/$T$3*E14*$J14*O$2*EXP(O$3/$T$4/$K27) -> #DIV/0! | P14: =1/P$4/$T$2/$T$3*F14*$J14*P$2*EXP(P$3/$T$4/$K27) -> #DIV/0! | Q14: =1/Q$4/$T$2/$T$3*G14*$J14*Q$2*EXP(Q$3/$T$4/$K27) -> #DIV/0!
A15: ='Lines by Gauss'!B65 -> 2.8675 | B15: ='Lines by Gauss'!C65 -> 0 | C15: ='Lines by Gauss'!D65 -> 2281.1893 | D15: ='Lines by Gauss'!E65 -> 2281.1893 | E15: ='Lines by Gauss'!F65 -> 792.32501 | F15: ='Lines by Gauss'!G65 -> 0 | G15: ='Lines by Gauss'!H65 -> 1195.6114 | J15: =VLOOKUP($K28,'Partition function'!$A:$B,2,FALSE) -> #DIV/0! | K15: =A15 -> 2.8675 | L15: =1/L$4/$T$2/$T$3*B15*$J15*L$2*EXP(L$3/$T$4/$K28) -> #DIV/0! | M15: =1/M$4/$T$2/$T$3*C15*$J15*M$2*EXP(M$3/$T$4/$K28) -> #DIV/0! | N15: =1/N$4/$T$2/$T$3*D15*$J15*N$2*EXP(N$3/$T$4/$K28) -> #DIV/0! | O15: =1/O$4/$T$2/$T$3*E15*$J15*O$2*EXP(O$3/$T$4/$K28) -> #DIV/0! | P15: =1/P$4/$T$2/$T$3*F15*$J15*P$2*EXP(P$3/$T$4/$K28) -> #DIV/0! | Q15: =1/Q$4/$T$2/$T$3*G15*$J15*Q$2*EXP(Q$3/$T$4/$K28) -> #DIV/0!
J18: r, mm | K18: T, K | L18: dT, K | M18: a | N18: da | P18: b | Q18: db | S18: n, m-3 | T18: dn, m-3
A19: =A6 -> 0 | B19: =LN(B6*B$2^3/B$4) -> #NUM! | C19: =LN(C6*C$2^3/C$4) -> 32.055284 | D19: =LN(D6*D$2^3/D$4) -> 27.657336 | E19: =LN(E6*E$2^3/E$4) -> 27.055975 | F19: =LN(F6*F$2^3/F$4) -> #NUM! | G19: =LN(G6*G$2^3/G$4) -> 31.986325 | J19: =A6 -> 0 | K19: =ROUND(-11600/M19,0) -> #DIV/0! | L19: =ROUND(-K19*N19/M19,0) -> #DIV/0! | M19: =W20 -> 0 | N19: =X20 -> 0 | P19: =W19 -> 0 | Q19: =X19 -> 0 | S19: =EXP(P19)*J6/66700000000000/$T$3/$T$2*0.000000001 -> #DIV/0! | T19: =Q19*S19/P19 -> #DIV/0! | V19: b1
A20: =A7 -> 0.31861111 | B20: =LN(B7*B$2^3/B$4) -> #NUM! | C20: =LN(C7*C$2^3/C$4) -> 32.03446 | D20: =LN(D7*D$2^3/D$4) -> 27.636511 | E20: =LN(E7*E$2^3/E$4) -> 27.035769 | F20: =LN(F7*F$2^3/F$4) -> #NUM! | G20: =LN(G7*G$2^3/G$4) -> 31.96662 | J20: =A7 -> 0.31861111 | K20: =ROUND(-11600/M20,0) -> #DIV/0! | L20: =ROUND(-K20*N20/M20,0) -> #DIV/0! | M20: =W22 -> 0 | N20: =X22 -> 0 | P20: =W21 -> 0 | Q20: =X21 -> 0 | S20: =EXP(P20)*J7/66700000000000/$T$3/$T$2*0.000000001 -> #DIV/0! | T20: =Q20*S20/P20 -> #DIV/0! | V20: a1
A21: =A8 -> 0.63722222 | B21: =LN(B8*B$2^3/B$4) -> #NUM! | C21: =LN(C8*C$2^3/C$4) -> 31.971146 | D21: =LN(D8*D$2^3/D$4) -> 27.573197 | E21: =LN(E8*E$2^3/E$4) -> 26.927012 | F21: =LN(F8*F$2^3/F$4) -> #NUM! | G21: =LN(G8*G$2^3/G$4) -> 31.907385 | J21: =A8 -> 0.63722222 | K21: =ROUND(-11600/M21,0) -> #DIV/0! | L21: =ROUND(-K21*N21/M21,0) -> #DIV/0! | M21: =W24 -> 0 | N21: =X24 -> 0 | P21: =W23 -> 0 | Q21: =X23 -> 0 | S21: =EXP(P21)*J8/66700000000000/$T$3/$T$2*0.000000001 -> #DIV/0! | T21: =Q21*S21/P21 -> #DIV/0! | V21: b2
A22: =A9 -> 0.95583333 | B22: =LN(B9*B$2^3/B$4) -> #NUM! | C22: =LN(C9*C$2^3/C$4) -> 31.863596 | D22: =LN(D9*D$2^3/D$4) -> 27.465647 | E22: =LN(E9*E$2^3/E$4) -> 26.777561 | F22: =LN(F9*F$2^3/F$4) -> #NUM! | G22: =LN(G9*G$2^3/G$4) -> 31.80893 | J22: =A9 -> 0.95583333 | K22: =ROUND(-11600/M22,0) -> #DIV/0! | L22: =ROUND(-K22*N22/M22,0) -> #DIV/0! | M22: =W26 -> 0 | N22: =X26 -> 0 | P22: =W25 -> 0 | Q22: =X25 -> 0 | S22: =EXP(P22)*J9/66700000000000/$T$3/$T$2*0.000000001 -> #DIV/0! | T22: =Q22*S22/P22 -> #DIV/0! | V22: a2
A23: =A10 -> 1.2744444 | B23: =LN(B10*B$2^3/B$4) -> #NUM! | C23: =LN(C10*C$2^3/C$4) -> 31.717544 | D23: =LN(D10*D$2^3/D$4) -> 27.319595 | E23: =LN(E10*E$2^3/E$4) -> 26.538437 | F23: =LN(F10*F$2^3/F$4) -> #NUM! | G23: =LN(G10*G$2^3/G$4) -> 31.67083 | J23: =A10 -> 1.2744444 | K23: =ROUND(-11600/M23,0) -> #DIV/0! | L23: =ROUND(-K23*N23/M23,0) -> #DIV/0! | M23: =W28 -> 0 | N23: =X28 -> 0 | P23: =W27 -> 0 | Q23: =X27 -> 0 | S23: =EXP(P23)*J10/66700000000000/$T$3/$T$2*0.000000001 -> #DIV/0! | T23: =Q23*S23/P23 -> #DIV/0! | V23: b3
A24: =A11 -> 1.5930556 | B24: =LN(B11*B$2^3/B$4) -> #NUM! | C24: =LN(C11*C$2^3/C$4) -> 31.528052 | D24: =LN(D11*D$2^3/D$4) -> 27.130103 | E24: =LN(E11*E$2^3/E$4) -> 26.260248 | F24: =LN(F11*F$2^3/F$4) -> #NUM! | G24: =LN(G11*G$2^3/G$4) -> 31.495161 | J24: =A11 -> 1.5930556 | K24: =ROUND(-11600/M24,0) -> #DIV/0! | L24: =ROUND(-K24*N24/M24,0) -> #DIV/0! | M24: =W30 -> 0 | N24: =X30 -> 0 | P24: =W29 -> 0 | Q24: =X29 -> 0 | S24: =EXP(P24)*J11/66700000000000/$T$3/$T$2*0.000000001 -> #DIV/0! | T24: =Q24*S24/P24 -> #DIV/0! | V24: a3
A25: =A12 -> 1.9116667 | B25: =LN(B12*B$2^3/B$4) -> #NUM! | C25: =LN(C12*C$2^3/C$4) -> 31.300946 | D25: =LN(D12*D$2^3/D$4) -> 26.902997 | E25: =LN(E12*E$2^3/E$4) -> 25.89499 | F25: =LN(F12*F$2^3/F$4) -> #NUM! | G25: =LN(G12*G$2^3/G$4) -> 31.284204 | J25: =A12 -> 1.9116667 | K25: =ROUND(-11600/M25,0) -> #DIV/0! | L25: =ROUND(-K25*N25/M25,0) -> #DIV/0! | M25: =W32 -> 0 | N25: =X32 -> 0 | P25: =W31 -> 0 | Q25: =X31 -> 0 | S25: =EXP(P25)*J12/66700000000000/$T$3/$T$2*0.000000001 -> #DIV/0! | T25: =Q25*S25/P25 -> #DIV/0! | V25: b4
A26: =A13 -> 2.2302778 | B26: =LN(B13*B$2^3/B$4) -> #NUM! | C26: =LN(C13*C$2^3/C$4) -> 31.025097 | D26: =LN(D13*D$2^3/D$4) -> 26.627148 | E26: =LN(E13*E$2^3/E$4) -> 25.494561 | F26: =LN(F13*F$2^3/F$4) -> #NUM! | G26: =LN(G13*G$2^3/G$4) -> 31.039988 | J26: =A13 -> 2.2302778 | K26: =ROUND(-11600/M26,0) -> #DIV/0! | L26: =ROUND(-K26*N26/M26,0) -> #DIV/0! | M26: =W34 -> 0 | N26: =X34 -> 0 | P26: =W33 -> 0 | Q26: =X33 -> 0 | S26: =EXP(P26)*J13/66700000000000/$T$3/$T$2*0.000000001 -> #DIV/0! | T26: =Q26*S26/P26 -> #DIV/0! | V26: a4
A27: =A14 -> 2.5488889 | B27: =LN(B14*B$2^3/B$4) -> #NUM! | C27: =LN(C14*C$2^3/C$4) -> 30.714922 | D27: =LN(D14*D$2^3/D$4) -> 26.316973 | E27: =LN(E14*E$2^3/E$4) -> 25.020249 | F27: =LN(F14*F$2^3/F$4) -> #NUM! | G27: =LN(G14*G$2^3/G$4) -> 30.753981 | J27: =A14 -> 2.5488889 | K27: =ROUND(-11600/M27,0) -> #DIV/0! | L27: =ROUND(-K27*N27/M27,0) -> #DIV/0! | M27: =W36 -> 0 | N27: =X36 -> 0 | P27: =W35 -> 0 | Q27: =X35 -> 0 | S27: =EXP(P27)*J14/66700000000000/$T$3/$T$2*0.000000001 -> #DIV/0! | T27: =Q27*S27/P27 -> #DIV/0! | V27: b5
A28: =A15 -> 2.8675 | B28: =LN(B15*B$2^3/B$4) -> #NUM! | C28: =LN(C15*C$2^3/C$4) -> 30.366076 | D28: =LN(D15*D$2^3/D$4) -> 25.968127 | E28: =LN(E15*E$2^3/E$4) -> 24.768058 | F28: =LN(F15*F$2^3/F$4) -> #NUM! | G28: =LN(G15*G$2^3/G$4) -> 30.509044 | J28: =A15 -> 2.8675 | K28: =ROUND(-11600/M28,0) -> #DIV/0! | L28: =ROUND(-K28*N28/M28,0) -> #DIV/0! | M28: =W38 -> 0 | N28: =X38 -> 0 | P28: =W37 -> 0 | Q28: =X37 -> 0 | S28: =EXP(P28)*J15/66700000000000/$T$3/$T$2*0.000000001 -> #DIV/0! | T28: =Q28*S28/P28 -> #DIV/0! | V28: a5
V29: b6
V30: a6
A31: Levels populations | V31: b7
A32: λ, nm | B32: =B2*0.000000001 -> 4.651119e-07 | C32: =C2*0.000000001 -> 5.105537e-07 | D32: =D2*0.000000001 -> 5.15323e-07 | E32: =E2*0.000000001 -> 5.218197e-07 | F32: =F2*0.000000001 -> 5.700237e-07 | G32: =G2*0.000000001 -> 5.782127e-07 | V32: a7
A33: Ek, J | B33: 7.737547 | C33: 3.816948 | D33: 6.191593 | E33: 6.192444 | F33: 3.816948 | G33: 3.78615 | V33: b8
A34: gk | B34: 8 | C34: 4 | D34: 4 | E34: 6 | F34: 4 | G34: 2 | V34: a8
A35: A, 1/S | B35: =66700000000000*B4/B2/B2/B34 -> 54796431 | C35: =66700000000000*C4/C2/C2/C34 -> 1260228.3 | D35: =66700000000000*D4/D2/D2/D34 -> 1.0339327e+08 | E35: =66700000000000*E4/E2/E2/E34 -> 80494758 | F35: =66700000000000*F4/F2/F2/F34 -> 289981.11 | G35: =66700000000000*G4/G2/G2/G34 -> 1296772.9 | J35: ln(n_4651) | K35: ln(n_5105) | L35: ln(n_5153) | M35: ln(n_5218) | N35: ln(n_5700) | O35: ln(n_5782) | V35: b9
A36: r, mm | B36: n_4651 | C36: n_5105 | D36: n_5153 | E36: n_5218 | F36: n_5700 | G36: n_5782 | I36: r, mm | J36: 7.737547 | K36: 3.816948 | L36: 6.191593 | M36: 6.192444 | N36: 3.816948 | O36: 3.78615 | V36: a9
A37: =A6 -> 0 | B37: =1/$T$3/$T$2/B$35*B$32*B6 -> 0 | C37: =1/$T$3/$T$2/C$35*C$32*C6 -> 2.5161269e+16 | D37: =1/$T$3/$T$2/D$35*D$32*D6 -> 3.0954771e+14 | E37: =1/$T$3/$T$2/E$35*E$32*E6 -> 2.5447862e+14 | F37: =1/$T$3/$T$2/F$35*F$32*F6 -> 0 | G37: =1/$T$3/$T$2/G$35*G$32*G6 -> 1.1742323e+16 | I37: =A37 -> 0 | J37: =LN(B37/B$34) -> #NUM! | K37: =LN(C37/C$34) -> 36.377788 | L37: =LN(D37/D$34) -> 31.979839 | M37: =LN(E37/E$34) -> 31.378478 | N37: =LN(F37/F$34) -> #NUM! | O37: =LN(G37/G$34) -> 36.308829 | V37: b10
A38: =A7 -> 0.31861111 | B38: =1/$T$3/$T$2/B$35*B$32*B7 -> 0 | C38: =1/$T$3/$T$2/C$35*C$32*C7 -> 2.464272e+16 | D38: =1/$T$3/$T$2/D$35*D$32*D7 -> 303168239937248 | E38: =1/$T$3/$T$2/E$35*E$32*E7 -> 2.4938814e+14 | F38: =1/$T$3/$T$2/F$35*F$32*F7 -> 0 | G38: =1/$T$3/$T$2/G$35*G$32*G7 -> 1.1513196e+16 | I38: =A38 -> 0.31861111 | J38: =LN(B38/B$34) -> #NUM! | K38: =LN(C38/C$34) -> 36.356964 | L38: =LN(D38/D$34) -> 31.959015 | M38: =LN(E38/E$34) -> 31.358272 | N38: =LN(F38/F$34) -> #NUM! | O38: =LN(G38/G$34) -> 36.289123 | V38: a10
A39: =A8 -> 0.63722222 | B39: =1/$T$3/$T$2/B$35*B$32*B8 -> 0 | C39: =1/$T$3/$T$2/C$35*C$32*C8 -> 2.3130847e+16 | D39: =1/$T$3/$T$2/D$35*D$32*D8 -> 2.8456835e+14 | E39: =1/$T$3/$T$2/E$35*E$32*E8 -> 2.2368843e+14 | F39: =1/$T$3/$T$2/F$35*F$32*F8 -> 0 | G39: =1/$T$3/$T$2/G$35*G$32*G8 -> 1.0851021e+16 | I39: =A39 -> 0.63722222 | J39: =LN(B39/B$34) -> #NUM! | K39: =LN(C39/C$34) -> 36.293649 | L39: =LN(D39/D$34) -> 31.8957 | M39: =LN(E39/E$34) -> 31.249516 | N39: =LN(F39/F$34) -> #NUM! | O39: =LN(G39/G$34) -> 36.229888
